Workbook

Sheet Instrucciones
A1: CHECKLIST QA — MATRIZ DE CUMPLIMIENTO RF / CASOS DE USO EXTENDIDO / HISTORIAS DE USUARIO
A5: Mercapleno
A10: Hojas incluidas
A11: • Checklist RF Verificación de Requisitos Funcionales.
A12: • Checklist CP Verificación de Casos de Prueba.
A13: • Checklist HU Verificación de Historias de Usuario.
A14: • Resumen Panel con el conteo y porcentaje de cumplimiento por cada hoja.

Sheet Checklist RF
B1: CHECKLIST QA — VERIFICACIÓN DE REQUISITOS FUNCIONALES (RF)
A2: N° de RF | B2: ID RF | C2: Nombre del Requisito | D2: Redacción clara, sin ambigüedad | E2: Trazabilidad a HU / módulo | F2: Verbo modal correcto (debe / deberá) | G2: Sin contradicciones internas | H2: Criterio de aceptación verificable/medible | I2: Prioridad definida | J2: Reglas de negocio | K2: Precondicion definida | L2: Entradas definidas | M2: Flujo principal | N2: Salidas esperadas | O2: % Cumplimiento | P2: Estado General | Q2: Observaciones
B3: RF-001 | C3: Autenticación
A4: RF-001 | B4: RF-001.1 | C4: Registrar usuario | D4: ✓ | E4: ✓ | F4: ✓ | G4: ⚠ | H4: ✓ | I4: ✓ | J4: ✓ | K4: ✓ | L4: ✓ | M4: ✓ | N4: ✓ | O4: =IF(COUNTA(D4:N4)=0,"",(COUNTIF(D4:N4,"✓")+COUNTIF(D4:N4,"⚠")*0.5)/11) -> 0.95454545 | P4: =IF(O4="","",IF(O4>=0.9,"CUMPLE",IF(O4>=0.6,"CUMPLE PARCIAL","NO CUMPLE"))) -> CUMPLE | Q4: Solo se indica que debe tener un mínimo de 8 caracteres. No se especifica si debe incluir mayúsculas, minúsculas, números o caracteres especiales.
A5: RF-002 | B5: RF-001.2 | C5: Verificar correo electrónico | D5: ✓ | E5: ✓ | F5: ✓ | G5: ✓ | H5: ✓ | I5: ✓ | J5: ✓ | K5: ✓ | L5: ✓ | M5: ✓ | N5: ✓ | O5: =IF(COUNTA(D5:N5)=0,"",(COUNTIF(D5:N5,"✓")+COUNTIF(D5:N5,"⚠")*0.5)/11) -> 1 | P5: =IF(O5="","",IF(O5>=0.9,"CUMPLE",IF(O5>=0.6,"CUMPLE PARCIAL","NO CUMPLE"))) -> CUMPLE
A6: RF-003 | B6: RF-001.3 | C6: Reenviar código de verificación | D6: ✓ | E6: ✓ | F6: ✓ | G6: ⚠ | H6: ✓ | I6: ✓ | J6: ✓ | K6: ✓ | L6: ✓ | M6: ✓ | N6: ✓ | O6: =IF(COUNTA(D6:N6)=0,"",(COUNTIF(D6:N6,"✓")+COUNTIF(D6:N6,"⚠")*0.5)/11) -> 0.95454545 | P6: =IF(O6="","",IF(O6>=0.9,"CUMPLE",IF(O6>=0.6,"CUMPLE PARCIAL","NO CUMPLE"))) -> CUMPLE | Q6: Falta indicar si existe un límite de reenvios
A7: RF-004 | B7: RF-001.4 | C7: Inicar sesión | D7: ⚠ | E7: ✓ | F7: ✓ | G7: ✓ | H7: ✓ | I7: ✓ | J7: ✓ | K7: ✓ | L7: ✓ | M7: ✓ | N7: ✓ | O7: =IF(COUNTA(D7:N7)=0,"",(COUNTIF(D7:N7,"✓")+COUNTIF(D7:N7,"⚠")*0.5)/11) -> 0.95454545 | P7: =IF(O7="","",IF(O7>=0.9,"CUMPLE",IF(O7>=0.6,"CUMPLE PARCIAL","NO CUMPLE"))) -> CUMPLE | Q7: Verifica que no nombre el cifrado con Bcrypt, ya que es parte del codigo
A8: RF-005 | B8: RF-001.5 | C8: Doble factor | D8: ✓ | E8: ✓ | F8: ✓ | G8: ✓ | H8: ✓ | I8: ✓ | J8: ✓ | K8: ✓ | L8: ⚠ | M8: ✓ | N8: ✓ | O8: =IF(COUNTA(D8:N8)=0,"",(COUNTIF(D8:N8,"✓")+COUNTIF(D8:N8,"⚠")*0.5)/11) -> 0.95454545 | P8: =IF(O8="","",IF(O8>=0.9,"CUMPLE",IF(O8>=0.6,"CUMPLE PARCIAL","NO CUMPLE"))) -> CUMPLE | Q8: Se recomienda hacer más explícita la generación y entrega del token temporal
A9: RF-006 | B9: RF-001.6 | C9: Verificar código de doble factor(2FA) | D9: ✓ | E9: ✓ | F9: ✓ | G9: ✓ | H9: ✓ | I9: ✓ | J9: ✓ | K9: ✓ | L9: ✓ | M9: ✓ | N9: ✓ | O9: =IF(COUNTA(D9:N9)=0,"",(COUNTIF(D9:N9,"✓")+COUNTIF(D9:N9,"⚠")*0.5)/11) -> 1 | P9: =IF(O9="","",IF(O9>=0.9,"CUMPLE",IF(O9>=0.6,"CUMPLE PARCIAL","NO CUMPLE"))) -> CUMPLE
A10: RF-007 | B10: RF-001.7 | C10: Solicitar recuperación de contraseña | D10: ✓ | E10: ✓ | F10: ✓ | G10: ✓ | H10: ✓ | I10: ✓ | J10: ✓ | K10: ✓ | L10: ✓ | M10: ✓ | N10: ✓ | O10: =IF(COUNTA(D10:N10)=0,"",(COUNTIF(D10:N10,"✓")+COUNTIF(D10:N10,"⚠")*0.5)/11) -> 1 | P10: =IF(O10="","",IF(O10>=0.9,"CUMPLE",IF(O10>=0.6,"CUMPLE PARCIAL","NO CUMPLE"))) -> CUMPLE | Q10: Se recomienda definir el comportamiento esperado cuando un usuario tenga múltiples sesiones activas y precisar el resultado esperado de la invalidación del token JWT
A11: RF-008 | B11: RF-001.8 | C11: Restablecer contraseña | D11: ✓ | E11: ✓ | F11: ✓ | G11: ✓ | H11: ✓ | I11: ✓ | J11: ✓ | K11: ✓ | L11: ✓ | M11: ✓ | N11: ✓ | O11: =IF(COUNTA(D11:N11)=0,"",(COUNTIF(D11:N11,"✓")+COUNTIF(D11:N11,"⚠")*0.5)/11) -> 1 | P11: =IF(O11="","",IF(O11>=0.9,"CUMPLE",IF(O11>=0.6,"CUMPLE PARCIAL","NO CUMPLE"))) -> CUMPLE | Q11: Se recomienda especificar el comportamiento cuando se solicitan múltiples códigos de recuperación antes de que expire el anterior y, si aplica
A12: RF-009 | B12: RF-001.9 | C12: Cerrar sesión | D12: ✓ | E12: ✓ | F12: ✓ | G12: ✓ | H12: ✓ | I12: ✓ | J12: ✓ | K12: ✓ | L12: ✓ | M12: ✓ | N12: ✓ | O12: =IF(COUNTA(D12:N12)=0,"",(COUNTIF(D12:N12,"✓")+COUNTIF(D12:N12,"⚠")*0.5)/11) -> 1 | P12: =IF(O12="","",IF(O12>=0.9,"CUMPLE",IF(O12>=0.6,"CUMPLE PARCIAL","NO CUMPLE"))) -> CUMPLE
B13: RF-002 | C13: Gestión de usuarios | O13: =IF(COUNTA(D13:J13)=0,"",(COUNTIF(D13:J13,"✓")+COUNTIF(D13:J13,"⚠")*0.5)/8) | P13: =IF(O13="","",IF(O13>=0.9,"CUMPLE",IF(O13>=0.6,"CUMPLE PARCIAL","NO CUMPLE")))
A14: RF-010 | B14: RF-002.1 | C14: Registrar usuario | D14: ✓ | E14: ✓ | F14: ✓ | G14: ✓ | H14: ✓ | I14: ✓ | J14: ✓ | K14: ✓ | L14: ✓ | M14: ✓ | N14: ✓ | O14: =IF(COUNTA(D14:N14)=0,"",(COUNTIF(D14:N14,"✓")+COUNTIF(D14:N14,"⚠")*0.5)/11) -> 1 | P14: =IF(O14="","",IF(O14>=0.9,"CUMPLE",IF(O14>=0.6,"CUMPLE PARCIAL","NO CUMPLE"))) -> CUMPLE
A15: RF-011 | B15: RF-002.2 | C15: Consultar usuario | D15: ✓ | E15: ✓ | F15: ✓ | G15: ✓ | H15: ✓ | I15: ✓ | J15: ✓ | K15: ✓ | L15: ✓ | M15: ✓ | N15: ✓ | O15: =IF(COUNTA(D15:N15)=0,"",(COUNTIF(D15:N15,"✓")+COUNTIF(D15:N15,"⚠")*0.5)/11) -> 1 | P15: =IF(O15="","",IF(O15>=0.9,"CUMPLE",IF(O15>=0.6,"CUMPLE PARCIAL","NO CUMPLE"))) -> CUMPLE | Q15: Como mejora, se recomienda especificar los criterios de búsqueda permitidos y definir exactamente qué información debe visualizarse al consultar un usuario
A16: RF-012 | B16: RF-002.3 | C16: Actualizar usuario | D16: ✓ | E16: ✓ | F16: ✓ | G16: ✓ | H16: ✓ | I16: ✓ | J16: ✓ | K16: ✓ | L16: ✓ | M16: ✓ | N16: ✓ | O16: =IF(COUNTA(D16:N16)=0,"",(COUNTIF(D16:N16,"✓")+COUNTIF(D16:N16,"⚠")*0.5)/11) -> 1 | P16: =IF(O16="","",IF(O16>=0.9,"CUMPLE",IF(O16>=0.6,"CUMPLE PARCIAL","NO CUMPLE"))) -> CUMPLE
A17: RF-013 | B17: RF-002.4 | C17: Eliminar usuario | D17: ✓ | E17: ✓ | F17: ✓ | G17: ✓ | H17: ✓ | I17: ✓ | J17: ✓ | K17: ✓ | L17: ✓ | M17: ✓ | N17: ✓ | O17: =IF(COUNTA(D17:N17)=0,"",(COUNTIF(D17:N17,"✓")+COUNTIF(D17:N17,"⚠")*0.5)/11) -> 1 | P17: =IF(O17="","",IF(O17>=0.9,"CUMPLE",IF(O17>=0.6,"CUMPLE PARCIAL","NO CUMPLE"))) -> CUMPLE | Q17: Como mejora, se recomienda especificar si la eliminación es lógica o física, definir las restricciones de eliminación
B18: RF-003 | C18: Gestión de Catálogo y Compras | D18: Gestión de Catálogo y Compras
A19: RF-014 | B19: RF-003.1 | C19: Consultar Catálogo de Productos | D19: ✓ | E19: ✓ | F19: ✓ | G19: ✓ | H19: ✓ | I19: ✓ | J19: ✓ | K19: ✓ | L19: ✓ | M19: ✓ | N19: ✓ | O19: =IF(COUNTA(D19:N19)=0,"",(COUNTIF(D19:N19,"✓")+COUNTIF(D19:N19,"⚠")*0.5)/11) -> 1 | P19: =IF(O19="","",IF(O19>=0.9,"CUMPLE",IF(O19>=0.6,"CUMPLE PARCIAL","NO CUMPLE"))) -> CUMPLE
A20: RF-015 | B20: RF-003.2 | C20: Filtrado y Búsqueda de Productos | D20: ✓ | E20: ✓ | F20: ✓ | G20: ✓ | H20: ✓ | I20: ✓ | J20: ✓ | K20: ✓ | L20: ✓ | M20: ✓ | N20: ✓ | O20: =IF(COUNTA(D20:N20)=0,"",(COUNTIF(D20:N20,"✓")+COUNTIF(D20:N20,"⚠")*0.5)/11) -> 1 | P20: =IF(O20="","",IF(O20>=0.9,"CUMPLE",IF(O20>=0.6,"CUMPLE PARCIAL","NO CUMPLE"))) -> CUMPLE
A21: RF-016 | B21: RF-003.3 | C21: Agregar Producto al Carrito. | D21: ✓ | E21: ✓ | F21: ✓ | G21: ✓ | H21: ✓ | I21: ✓ | J21: ✓ | K21: ✓ | L21: ✓ | M21: ✓ | N21: ✓ | O21: =IF(COUNTA(D21:N21)=0,"",(COUNTIF(D21:N21,"✓")+COUNTIF(D21:N21,"⚠")*0.5)/11) -> 1 | P21: =IF(O21="","",IF(O21>=0.9,"CUMPLE",IF(O21>=0.6,"CUMPLE PARCIAL","NO CUMPLE"))) -> CUMPLE
A22: RF-017 | B22: RF-003.4 | C22: Visualizar Carrito de Compras | D22: ✓ | E22: ✓ | F22: ✓ | G22: ✓ | H22: ✓ | I22: ✓ | J22: ✓ | K22: ✓ | L22: ✓ | M22: ✓ | N22: ✓ | O22: =IF(COUNTA(D22:N22)=0,"",(COUNTIF(D22:N22,"✓")+COUNTIF(D22:N22,"⚠")*0.5)/11) -> 1 | P22: =IF(O22="","",IF(O22>=0.9,"CUMPLE",IF(O22>=0.6,"CUMPLE PARCIAL","NO CUMPLE"))) -> CUMPLE
A23: RF-018 | B23: RF-003.5 | C23: Modificar Cantidades en Carrito | D23: ✓ | E23: ✓ | F23: ✓ | G23: ✓ | H23: ✓ | I23: ✓ | J23: ✓ | K23: ✓ | L23: ✓ | M23: ✓ | N23: ✓ | O23: =IF(COUNTA(D23:N23)=0,"",(COUNTIF(D23:N23,"✓")+COUNTIF(D23:N23,"⚠")*0.5)/11) -> 1 | P23: =IF(O23="","",IF(O23>=0.9,"CUMPLE",IF(O23>=0.6,"CUMPLE PARCIAL","NO CUMPLE"))) -> CUMPLE
A24: RF-019 | B24: RF-003.6 | C24: Seleccionar Método de Pago | D24: ✓ | E24: ✓ | F24: ✓ | G24: ✓ | H24: ✓ | I24: ✓ | J24: ✓ | K24: ✓ | L24: ✓ | M24: ✓ | N24: ✓ | O24: =IF(COUNTA(D24:N24)=0,"",(COUNTIF(D24:N24,"✓")+COUNTIF(D24:N24,"⚠")*0.5)/11) -> 1 | P24: =IF(O24="","",IF(O24>=0.9,"CUMPLE",IF(O24>=0.6,"CUMPLE PARCIAL","NO CUMPLE"))) -> CUMPLE
A25: RF-020 | B25: RF-003.7 | C25: Confirmar Compra | D25: ✓ | E25: ✓ | F25: ✓ | G25: ✓ | H25: ✓ | I25: ✓ | J25: ✓ | K25: ✓ | L25: ✓ | M25: ✓ | N25: ✓ | O25: =IF(COUNTA(D25:N25)=0,"",(COUNTIF(D25:N25,"✓")+COUNTIF(D25:N25,"⚠")*0.5)/11) -> 1 | P25: =IF(O25="","",IF(O25>=0.9,"CUMPLE",IF(O25>=0.6,"CUMPLE PARCIAL","NO CUMPLE"))) -> CUMPLE
A26: RF-021 | B26: RF-003.8 | C26: Comprobante de Venta | D26: ⚠ | E26: ✓ | F26: ✓ | G26: ✓ | H26: ✓ | I26: ✓ | J26: ✓ | K26: ✓ | L26: ✓ | M26: ✓ | N26: ✓ | O26: =IF(COUNTA(D26:N26)=0,"",(COUNTIF(D26:N26,"✓")+COUNTIF(D26:N26,"⚠")*0.5)/11) -> 0.95454545 | P26: =IF(O26="","",IF(O26>=0.9,"CUMPLE",IF(O26>=0.6,"CUMPLE PARCIAL","NO CUMPLE"))) -> CUMPLE | Q26: El RF cuple correctamente con lla mayoria de puntos especificados, mas sin embargo con respeto al campo de "flujo alternativo", no ofrecio alguno, se relleno como un, "no aplica ".
B27: RF-004 | C27: Gestion de Productos | O27: =IF(COUNTA(D27:J27)=0,"",(COUNTIF(D27:J27,"✓")+COUNTIF(D27:J27,"⚠")*0.5)/8) | P27: =IF(O27="","",IF(O27>=0.9,"CUMPLE",IF(O27>=0.6,"CUMPLE PARCIAL","NO CUMPLE")))
A28: RF-022 | B28: RF-004.1 | C28: Registrar Producto | D28: ✓ | E28: ✓ | F28: ✓ | G28: ✓ | H28: ✓ | I28: ✓ | J28: ✓ | K28: ✓ | L28: ✓ | M28: ✓ | N28: ✓ | O28: =IF(COUNTA(D28:N28)=0,"",(COUNTIF(D28:N28,"✓")+COUNTIF(D28:N28,"⚠")*0.5)/11) -> 1 | P28: =IF(O28="","",IF(O28>=0.9,"CUMPLE",IF(O28>=0.6,"CUMPLE PARCIAL","NO CUMPLE"))) -> CUMPLE | Q28: no detalla los campos obligatorios ni sus formatos de validación (solo se infieren en el flujo principal: nombre, precio, categoría, proveedor, descripción, imagen).
A29: RF-023 | B29: RF-004.2 | C29: Listar / consultar productos | D29: ✓ | E29: ✓ | F29: ✓ | G29: ✓ | H29: ✓ | I29: ✓ | J29: ✓ | K29: ✓ | L29: ✓ | M29: ✓ | N29: ✓ | O29: =IF(COUNTA(D29:N29)=0,"",(COUNTIF(D29:N29,"✓")+COUNTIF(D29:N29,"⚠")*0.5)/11) -> 1 | P29: =IF(O29="","",IF(O29>=0.9,"CUMPLE",IF(O29>=0.6,"CUMPLE PARCIAL","NO CUMPLE"))) -> CUMPLE | Q29: la postcondición de éxito habla de "información actualizada" de forma general, generando una ligera inconsistencia sobre qué campos realmente se visualizan. Contiene un error de redacción ("rol Administrador.}")
A30: RF-024 | B30: RF-004.3 | C30: Actualizar producto | D30: ✓ | E30: ✓ | F30: ✓ | G30: ✓ | H30: ✓ | I30: ✓ | J30: ✓ | K30: ✓ | L30: ✓ | M30: ✓ | N30: ✓ | O30: =IF(COUNTA(D30:N30)=0,"",(COUNTIF(D30:N30,"✓")+COUNTIF(D30:N30,"⚠")*0.5)/11) -> 1 | P30: =IF(O30="","",IF(O30>=0.9,"CUMPLE",IF(O30>=0.6,"CUMPLE PARCIAL","NO CUMPLE"))) -> CUMPLE | Q30: . El único punto pendiente es el campo "Entradas", que queda vacío pese a que el flujo principal menciona los campos editables (nombre, precio, categoría, proveedor, imagen); estos deberían formalizarse en la sección de Entradas.
A31: RF-025 | B31: RF-004.4 | C31: Deshabilitar producto | D31: ✓ | E31: ✓ | F31: ✓ | G31: ✓ | H31: ✓ | I31: ✓ | J31: ✓ | K31: ✓ | L31: ✓ | M31: ✓ | N31: ✓ | O31: =IF(COUNTA(D31:N31)=0,"",(COUNTIF(D31:N31,"✓")+COUNTIF(D31:N31,"⚠")*0.5)/11) -> 1 | P31: =IF(O31="","",IF(O31>=0.9,"CUMPLE",IF(O31>=0.6,"CUMPLE PARCIAL","NO CUMPLE"))) -> CUMPLE | Q31: el nombre del requisito y el flujo principal usan el término "Deshabilitar", pero la Descripción y la Postcondición usan "eliminar" ("el producto queda eliminado del backend").
B32: RF-005 | C32: Gestión de reportes y estadísticas | O32: =IF(COUNTA(D32:J32)=0,"",(COUNTIF(D32:J32,"✓")+COUNTIF(D32:J32,"⚠")*0.5)/8) | P32: =IF(O32="","",IF(O32>=0.9,"CUMPLE",IF(O32>=0.6,"CUMPLE PARCIAL","NO CUMPLE")))
A33: RF-026 | B33: RF-005.1 | C33: Reporte de ventas por mes | D33: ✓ | E33: ✓ | F33: ✓ | G33: ✓ | H33: ✓ | I33: ✓ | J33: ✓ | K33: ✓ | L33: ✓ | M33: ✓ | N33: ✓ | O33: =IF(COUNTA(D33:N33)=0,"",(COUNTIF(D33:N33,"✓")+COUNTIF(D33:N33,"⚠")*0.5)/11) -> 1 | P33: =IF(O33="","",IF(O33>=0.9,"CUMPLE",IF(O33>=0.6,"CUMPLE PARCIAL","NO CUMPLE"))) -> CUMPLE
A34: RF-027 | B34: RF-005.2 | C34: Top productos | D34: ✓ | E34: ✓ | F34: ✓ | G34: ✓ | H34: ✓ | I34: ✓ | J34: ✓ | K34: ✓ | L34: ✓ | M34: ✓ | N34: ✓ | O34: =IF(COUNTA(D34:N34)=0,"",(COUNTIF(D34:N34,"✓")+COUNTIF(D34:N34,"⚠")*0.5)/11) -> 1 | P34: =IF(O34="","",IF(O34>=0.9,"CUMPLE",IF(O34>=0.6,"CUMPLE PARCIAL","NO CUMPLE"))) -> CUMPLE
A35: RF-028 | B35: RF-005.3 | C35: Resumen general | D35: ✓ | E35: ✓ | F35: ✓ | G35: ✓ | H35: ✓ | I35: ✓ | J35: ✓ | K35: ✓ | L35: ✓ | M35: ✓ | N35: ✓ | O35: =IF(COUNTA(D35:N35)=0,"",(COUNTIF(D35:N35,"✓")+COUNTIF(D35:N35,"⚠")*0.5)/11) -> 1 | P35: =IF(O35="","",IF(O35>=0.9,"CUMPLE",IF(O35>=0.6,"CUMPLE PARCIAL","NO CUMPLE"))) -> CUMPLE
A36: RF-029 | B36: RF-005.4 | C36: Exportar PDF | D36: ✓ | E36: ✓ | F36: ✓ | G36: ✓ | H36: ✓ | I36: ✓ | J36: ✓ | K36: ✓ | L36: ✓ | M36: ✓ | N36: ✓ | O36: =IF(COUNTA(D36:N36)=0,"",(COUNTIF(D36:N36,"✓")+COUNTIF(D36:N36,"⚠")*0.5)/11) -> 1 | P36: =IF(O36="","",IF(O36>=0.9,"CUMPLE",IF(O36>=0.6,"CUMPLE PARCIAL","NO CUMPLE"))) -> CUMPLE
B37: RF-006 | C37: Gestión de movimientos | O37: =IF(COUNTA(D37:J37)=0,"",(COUNTIF(D37:J37,"✓")+COUNTIF(D37:J37,"⚠")*0.5)/8) | P37: =IF(O37="","",IF(O37>=0.9,"CUMPLE",IF(O37>=0.6,"CUMPLE PARCIAL","NO CUMPLE")))
A38: RF-030 | B38: RF-006.1 | C38: Registro movimeintos | D38: ✓ | E38: ✓ | F38: ✓ | G38: ✓ | H38: ✓ | I38: ✓ | J38: ✓ | K38: ✓ | L38: ✓ | M38: ✓ | N38: ✓ | O38: =IF(COUNTA(D38:N38)=0,"",(COUNTIF(D38:N38,"✓")+COUNTIF(D38:N38,"⚠")*0.5)/11) -> 1 | P38: =IF(O38="","",IF(O38>=0.9,"CUMPLE",IF(O38>=0.6,"CUMPLE PARCIAL","NO CUMPLE"))) -> CUMPLE
A39: RF-031 | B39: RF-006.2 | C39: Notificación al administrador por bajo stock | D39: ✓ | E39: ✓ | F39: ✓ | G39: ✓ | H39: ✓ | I39: ✓ | J39: ✓ | K39: ✓ | L39: ✓ | M39: ✓ | N39: ✓ | O39: =IF(COUNTA(D39:N39)=0,"",(COUNTIF(D39:N39,"✓")+COUNTIF(D39:N39,"⚠")*0.5)/11) -> 1 | P39: =IF(O39="","",IF(O39>=0.9,"CUMPLE",IF(O39>=0.6,"CUMPLE PARCIAL","NO CUMPLE"))) -> CUMPLE
B40: RF-007 | C40: Gestión de proveedores | O40: =IF(COUNTA(D40:J40)=0,"",(COUNTIF(D40:J40,"✓")+COUNTIF(D40:J40,"⚠")*0.5)/8) | P40: =IF(O40="","",IF(O40>=0.9,"CUMPLE",IF(O40>=0.6,"CUMPLE PARCIAL","NO CUMPLE")))
...

Sheet Checklist CU
A1: CHECKLIST QA — VERIFICACIÓN DE CASOS DE USO EXTENDIDO (CU)
A2: ID CP | B2: RF / HU relacionado | C2: Título del caso de prueba | D2: Título descriptivo y claro | E2: Precondiciones definidas | F2: Pasos numerados y claros | G2: Datos de entrada especificados | H2: Resultado esperado definido | I2: Redacción sin ambigüedad | J2: Cobertura del criterio de aceptación | K2: % Cumplimiento | L2: Estado General | M2: Observaciones
B3: RF-001
A4: CU-001.1 | B4: RF-001.1 | C4: Registrar usuario | D4: ✓ | E4: ✓ | F4: ✓ | G4: ✓ | H4: ✓ | I4: ✓ | J4: ✓ | K4: =IF(COUNTA(D4:J4)=0,"",(COUNTIF(D4:J4,"✓")+COUNTIF(D4:J4,"⚠")*0.5)/7) -> 1 | L4: =IF(K4="","",IF(K4>=0.9,"CUMPLE",IF(K4>=0.6,"CUMPLE PARCIAL","NO CUMPLE"))) -> CUMPLE
A5: CU-001.2 | B5: RF-001.2 | C5: Verificar correo electrónico | D5: ✓ | E5: ✓ | F5: ✓ | G5: ✓ | H5: ✓ | I5: ✓ | J5: ✓ | K5: =IF(COUNTA(D5:J5)=0,"",(COUNTIF(D5:J5,"✓")+COUNTIF(D5:J5,"⚠")*0.5)/7) -> 1 | L5: =IF(K5="","",IF(K5>=0.9,"CUMPLE",IF(K5>=0.6,"CUMPLE PARCIAL","NO CUMPLE"))) -> CUMPLE
A6: CU-001.3 | B6: RF-001.3 | C6: Reenviar código de verificación | D6: ✓ | E6: ✓ | F6: ✓ | G6: ✓ | H6: ✓ | I6: ✓ | J6: ✓ | K6: =IF(COUNTA(D6:J6)=0,"",(COUNTIF(D6:J6,"✓")+COUNTIF(D6:J6,"⚠")*0.5)/7) -> 1 | L6: =IF(K6="","",IF(K6>=0.9,"CUMPLE",IF(K6>=0.6,"CUMPLE PARCIAL","NO CUMPLE"))) -> CUMPLE | M6: La enumeración de la FE y FA estan mal
A7: CU-001.4 | B7: RF-001.4 | C7: Inicar sesión | D7: ✓ | E7: ✓ | F7: ✓ | G7: ✓ | H7: ✓ | I7: ✓ | J7: ⚠ | K7: =IF(COUNTA(D7:J7)=0,"",(COUNTIF(D7:J7,"✓")+COUNTIF(D7:J7,"⚠")*0.5)/7) -> 0.92857143 | L7: =IF(K7="","",IF(K7>=0.9,"CUMPLE",IF(K7>=0.6,"CUMPLE PARCIAL","NO CUMPLE"))) -> CUMPLE | M7: El flujo del JWT debe alinearse con el 2FA
A8: CU-001.5 | B8: RF-001.5 | C8: Doble factor | D8: ✓ | E8: ⚠ | F8: ✓ | G8: ✓ | H8: ✓ | I8: ✓ | J8: ✓ | K8: =IF(COUNTA(D8:J8)=0,"",(COUNTIF(D8:J8,"✓")+COUNTIF(D8:J8,"⚠")*0.5)/7) -> 0.92857143 | L8: =IF(K8="","",IF(K8>=0.9,"CUMPLE",IF(K8>=0.6,"CUMPLE PARCIAL","NO CUMPLE"))) -> CUMPLE | M8: Precondición duplicada
A9: CU-001.6 | B9: RF-001.6 | C9: Verificar código de doble factor(2FA) | D9: ✓ | E9: ✓ | F9: ✓ | G9: ✓ | H9: ✓ | I9: ✓ | J9: ✓ | K9: =IF(COUNTA(D9:J9)=0,"",(COUNTIF(D9:J9,"✓")+COUNTIF(D9:J9,"⚠")*0.5)/7) -> 1 | L9: =IF(K9="","",IF(K9>=0.9,"CUMPLE",IF(K9>=0.6,"CUMPLE PARCIAL","NO CUMPLE"))) -> CUMPLE
A10: CU-001.7 | B10: RF-001.7 | C10: Solicitar recuperación de contraseña | D10: ✓ | E10: ✓ | F10: ✓ | G10: ✓ | H10: ✓ | I10: ✓ | J10: ✓ | K10: =IF(COUNTA(D10:J10)=0,"",(COUNTIF(D10:J10,"✓")+COUNTIF(D10:J10,"⚠")*0.5)/7) -> 1 | L10: =IF(K10="","",IF(K10>=0.9,"CUMPLE",IF(K10>=0.6,"CUMPLE PARCIAL","NO CUMPLE"))) -> CUMPLE | M10: Corregir la enumeración de trazabilidad
A11: CU-001.8 | B11: RF-001.8 | C11: Restablecer contraseña | D11: ✓ | E11: ✓ | F11: ✓ | G11: ✓ | H11: ✓ | I11: ✓ | J11: ✓ | K11: =IF(COUNTA(D11:J11)=0,"",(COUNTIF(D11:J11,"✓")+COUNTIF(D11:J11,"⚠")*0.5)/7) -> 1 | L11: =IF(K11="","",IF(K11>=0.9,"CUMPLE",IF(K11>=0.6,"CUMPLE PARCIAL","NO CUMPLE"))) -> CUMPLE
A12: CU-001.9 | B12: RF-001.9 | C12: Cerrar sesión | D12: ✓ | E12: ✓ | F12: ✓ | G12: ✓ | H12: ✓ | I12: ✓ | J12: ✓ | K12: =IF(COUNTA(D12:J12)=0,"",(COUNTIF(D12:J12,"✓")+COUNTIF(D12:J12,"⚠")*0.5)/7) -> 1 | L12: =IF(K12="","",IF(K12>=0.9,"CUMPLE",IF(K12>=0.6,"CUMPLE PARCIAL","NO CUMPLE"))) -> CUMPLE
B13: RF-002
A14: CU-002.1 | B14: RF-002.1 | C14: Registrar usuario | D14: ✓ | E14: ✓ | F14: ✓ | G14: ✓ | H14: ✓ | I14: ✓ | J14: ✓ | K14: =IF(COUNTA(D14:J14)=0,"",(COUNTIF(D14:J14,"✓")+COUNTIF(D14:J14,"⚠")*0.5)/7) -> 1 | L14: =IF(K14="","",IF(K14>=0.9,"CUMPLE",IF(K14>=0.6,"CUMPLE PARCIAL","NO CUMPLE"))) -> CUMPLE
A15: CU-002.2 | B15: RF-002.2 | C15: Consultar usuario | D15: ✓ | E15: ✓ | F15: ✓ | G15: ✓ | H15: ✓ | I15: ✓ | J15: ✓ | K15: =IF(COUNTA(D15:J15)=0,"",(COUNTIF(D15:J15,"✓")+COUNTIF(D15:J15,"⚠")*0.5)/7) -> 1 | L15: =IF(K15="","",IF(K15>=0.9,"CUMPLE",IF(K15>=0.6,"CUMPLE PARCIAL","NO CUMPLE"))) -> CUMPLE
A16: CU-002.3 | B16: RF-002.3 | C16: Actualizar usuario | D16: ✓ | E16: ✓ | F16: ✓ | G16: ✓ | H16: ✓ | I16: ✓ | J16: ✓ | K16: =IF(COUNTA(D16:J16)=0,"",(COUNTIF(D16:J16,"✓")+COUNTIF(D16:J16,"⚠")*0.5)/7) -> 1 | L16: =IF(K16="","",IF(K16>=0.9,"CUMPLE",IF(K16>=0.6,"CUMPLE PARCIAL","NO CUMPLE"))) -> CUMPLE
A17: CU-002.4 | B17: RF-002.4 | C17: Eliminar usuario | D17: ✓ | E17: ✓ | F17: ✓ | G17: ✓ | H17: ✓ | I17: ✓ | J17: ✓ | K17: =IF(COUNTA(D17:J17)=0,"",(COUNTIF(D17:J17,"✓")+COUNTIF(D17:J17,"⚠")*0.5)/7) -> 1 | L17: =IF(K17="","",IF(K17>=0.9,"CUMPLE",IF(K17>=0.6,"CUMPLE PARCIAL","NO CUMPLE"))) -> CUMPLE
B18: RF-003
A19: CU-003.1 | C19: Consultar Catálogo de Productos | D19: ✓ | E19: ✓ | F19: ✓ | G19: ✓ | H19: ✓ | I19: ✓ | J19: ✓ | K19: =IF(COUNTA(D19:J19)=0,"",(COUNTIF(D19:J19,"✓")+COUNTIF(D19:J19,"⚠")*0.5)/7) -> 1 | L19: =IF(K19="","",IF(K19>=0.9,"CUMPLE",IF(K19>=0.6,"CUMPLE PARCIAL","NO CUMPLE"))) -> CUMPLE
A20: CU-003.2 | C20: Filtrado y Búsqueda de Productos | D20: ✓ | E20: ✓ | F20: ✓ | G20: ✓ | H20: ✓ | I20: ✓ | J20: ✓ | K20: =IF(COUNTA(D20:J20)=0,"",(COUNTIF(D20:J20,"✓")+COUNTIF(D20:J20,"⚠")*0.5)/7) -> 1 | L20: =IF(K20="","",IF(K20>=0.9,"CUMPLE",IF(K20>=0.6,"CUMPLE PARCIAL","NO CUMPLE"))) -> CUMPLE
A21: CU-003.3 | C21: Agregar Producto al Carrito. | D21: ✓ | E21: ✓ | F21: ✓ | G21: ✓ | H21: ✓ | I21: ✓ | J21: ✓ | K21: =IF(COUNTA(D21:J21)=0,"",(COUNTIF(D21:J21,"✓")+COUNTIF(D21:J21,"⚠")*0.5)/7) -> 1 | L21: =IF(K21="","",IF(K21>=0.9,"CUMPLE",IF(K21>=0.6,"CUMPLE PARCIAL","NO CUMPLE"))) -> CUMPLE
A22: CU-003.4 | C22: Visualizar Carrito de Compras | D22: ✓ | E22: ✓ | F22: ✓ | G22: ✓ | H22: ✓ | I22: ✓ | J22: ✓ | K22: =IF(COUNTA(D22:J22)=0,"",(COUNTIF(D22:J22,"✓")+COUNTIF(D22:J22,"⚠")*0.5)/7) -> 1 | L22: =IF(K22="","",IF(K22>=0.9,"CUMPLE",IF(K22>=0.6,"CUMPLE PARCIAL","NO CUMPLE"))) -> CUMPLE
A23: CU-003.5 | C23: Modificar Cantidades en Carrito | D23: ✓ | E23: ✓ | F23: ✓ | G23: ✓ | H23: ✓ | I23: ✓ | J23: ✓ | K23: =IF(COUNTA(D23:J23)=0,"",(COUNTIF(D23:J23,"✓")+COUNTIF(D23:J23,"⚠")*0.5)/7) -> 1 | L23: =IF(K23="","",IF(K23>=0.9,"CUMPLE",IF(K23>=0.6,"CUMPLE PARCIAL","NO CUMPLE"))) -> CUMPLE
A24: CU-003.6 | C24: Seleccionar Método de Pago | D24: ✓ | E24: ✓ | F24: ✓ | G24: ✓ | H24: ✓ | I24: ✓ | J24: ✓ | K24: =IF(COUNTA(D24:J24)=0,"",(COUNTIF(D24:J24,"✓")+COUNTIF(D24:J24,"⚠")*0.5)/7) -> 1 | L24: =IF(K24="","",IF(K24>=0.9,"CUMPLE",IF(K24>=0.6,"CUMPLE PARCIAL","NO CUMPLE"))) -> CUMPLE
A25: CU-003.7 | C25: Confirmar Compra | D25: ✓ | E25: ✓ | F25: ✓ | G25: ✓ | H25: ✓ | I25: ✓ | J25: ✓ | K25: =IF(COUNTA(D25:J25)=0,"",(COUNTIF(D25:J25,"✓")+COUNTIF(D25:J25,"⚠")*0.5)/7) -> 1 | L25: =IF(K25="","",IF(K25>=0.9,"CUMPLE",IF(K25>=0.6,"CUMPLE PARCIAL","NO CUMPLE"))) -> CUMPLE
A26: CU-003.8 | C26: Comprobante de Venta | D26: ✓ | E26: ✓ | F26: ✓ | G26: ✓ | H26: ✓ | I26: ✓ | J26: ✓ | K26: =IF(COUNTA(D26:J26)=0,"",(COUNTIF(D26:J26,"✓")+COUNTIF(D26:J26,"⚠")*0.5)/7) -> 1 | L26: =IF(K26="","",IF(K26>=0.9,"CUMPLE",IF(K26>=0.6,"CUMPLE PARCIAL","NO CUMPLE"))) -> CUMPLE
B27: RF-004
A28: CU-004.1 | B28: RF-004.1 | C28: Registrar Producto | D28: ✓ | E28: ✓ | F28: ✗ | G28: ✓ | H28: ✓ | I28: ✓ | J28: ✓ | K28: =IF(COUNTA(D28:J28)=0,"",(COUNTIF(D28:J28,"✓")+COUNTIF(D28:J28,"⚠")*0.5)/7) -> 0.85714286 | L28: =IF(K28="","",IF(K28>=0.9,"CUMPLE",IF(K28>=0.6,"CUMPLE PARCIAL","NO CUMPLE"))) -> CUMPLE PARCIAL
A29: CU-004.2 | B29: RF-004.2 | C29: Listar / consultar productos | D29: ✓ | E29: ✓ | F29: ✓ | G29: ✓ | H29: ✓ | I29: ✓ | J29: ✓ | K29: =IF(COUNTA(D29:J29)=0,"",(COUNTIF(D29:J29,"✓")+COUNTIF(D29:J29,"⚠")*0.5)/7) -> 1 | L29: =IF(K29="","",IF(K29>=0.9,"CUMPLE",IF(K29>=0.6,"CUMPLE PARCIAL","NO CUMPLE"))) -> CUMPLE
A30: CU-004.3 | B30: RF-004.3 | C30: Actualizar producto | D30: ✓ | E30: ✓ | F30: ✓ | G30: ✓ | H30: ✓ | I30: ✓ | J30: ✓ | K30: =IF(COUNTA(D30:J30)=0,"",(COUNTIF(D30:J30,"✓")+COUNTIF(D30:J30,"⚠")*0.5)/7) -> 1 | L30: =IF(K30="","",IF(K30>=0.9,"CUMPLE",IF(K30>=0.6,"CUMPLE PARCIAL","NO CUMPLE"))) -> CUMPLE
A31: CU-004.4 | B31: RF-004.4 | C31: Deshabilitar producto | D31: ✓ | E31: ✓ | F31: ✗ | G31: ✓ | H31: ✓ | I31: ✓ | J31: ✓ | K31: =IF(COUNTA(D31:J31)=0,"",(COUNTIF(D31:J31,"✓")+COUNTIF(D31:J31,"⚠")*0.5)/7) -> 0.85714286 | L31: =IF(K31="","",IF(K31>=0.9,"CUMPLE",IF(K31>=0.6,"CUMPLE PARCIAL","NO CUMPLE"))) -> CUMPLE PARCIAL
B32: RF-005
A33: CU-005.1 | B33: RF-005.1 | C33: Reporte de ventas por mes | D33: ✓ | E33: ✓ | F33: ✓ | G33: ✓ | H33: ✓ | I33: ✓ | J33: ✓ | K33: =IF(COUNTA(D33:J33)=0,"",(COUNTIF(D33:J33,"✓")+COUNTIF(D33:J33,"⚠")*0.5)/7) -> 1 | L33: =IF(K33="","",IF(K33>=0.9,"CUMPLE",IF(K33>=0.6,"CUMPLE PARCIAL","NO CUMPLE"))) -> CUMPLE
A34: CU-005.2 | B34: RF-005.2 | C34: Top productos | D34: ✓ | E34: ✓ | F34: ✓ | G34: ✓ | H34: ✓ | I34: ✓ | J34: ✓ | K34: =IF(COUNTA(D34:J34)=0,"",(COUNTIF(D34:J34,"✓")+COUNTIF(D34:J34,"⚠")*0.5)/7) -> 1 | L34: =IF(K34="","",IF(K34>=0.9,"CUMPLE",IF(K34>=0.6,"CUMPLE PARCIAL","NO CUMPLE"))) -> CUMPLE
A35: CU-005.3 | B35: RF-005.3 | C35: Resumen general | D35: ✓ | E35: ✓ | F35: ✓ | G35: ✓ | H35: ✓ | I35: ✓ | J35: ✓ | K35: =IF(COUNTA(D35:J35)=0,"",(COUNTIF(D35:J35,"✓")+COUNTIF(D35:J35,"⚠")*0.5)/7) -> 1 | L35: =IF(K35="","",IF(K35>=0.9,"CUMPLE",IF(K35>=0.6,"CUMPLE PARCIAL","NO CUMPLE"))) -> CUMPLE
A36: CU-005.4 | B36: RF-005.4 | C36: Exportar PDF | D36: ✓ | E36: ✓ | F36: ✓ | G36: ✓ | H36: ✓ | I36: ✓ | J36: ✓ | K36: =IF(COUNTA(D36:J36)=0,"",(COUNTIF(D36:J36,"✓")+COUNTIF(D36:J36,"⚠")*0.5)/7) -> 1 | L36: =IF(K36="","",IF(K36>=0.9,"CUMPLE",IF(K36>=0.6,"CUMPLE PARCIAL","NO CUMPLE"))) -> CUMPLE
B37: RF-006
A38: CU-006.1 | B38: RF-006.1 | C38: Registro de Movimiento | D38: ✓ | E38: ✓ | F38: ✓ | G38: ✓ | H38: ✓ | I38: ✓ | J38: ✓ | K38: =IF(COUNTA(D38:J38)=0,"",(COUNTIF(D38:J38,"✓")+COUNTIF(D38:J38,"⚠")*0.5)/7) -> 1 | L38: =IF(K38="","",IF(K38>=0.9,"CUMPLE",IF(K38>=0.6,"CUMPLE PARCIAL","NO CUMPLE"))) -> CUMPLE
A39: CU-006.2 | B39: RF-006.2 | C39: Notificación al Administrador por Bajo Stock | D39: ✓ | E39: ✓ | F39: ✓ | G39: ✓ | H39: ✓ | I39: ✓ | J39: ✓ | K39: =IF(COUNTA(D39:J39)=0,"",(COUNTIF(D39:J39,"✓")+COUNTIF(D39:J39,"⚠")*0.5)/7) -> 1 | L39: =IF(K39="","",IF(K39>=0.9,"CUMPLE",IF(K39>=0.6,"CUMPLE PARCIAL","NO CUMPLE"))) -> CUMPLE
B40: RF-007
...

Sheet Checklist HU
A1: CHECKLIST QA — VERIFICACIÓN DE HISTORIAS DE USUARIO (HU)
A2: ID HU | B2: Título de la Historia de Usuario | C2: Formato Como/Quiero/ Para correcto | D2: Actor o rol definido | E2: Criterios de aceptación definidos (Given/When/Then) | F2: Trazabilidad a RF | G2: Priorización (Story points y Sprint) | H2: Testable / verificable | I2: Redacción sin ambigüedad | J2: Tamaño adecuado (cumple INVEST) | K2: Definition of Done definida | L2: % Cumplimiento | M2: Estado General | N2: Observaciones
B3: RF-001
A4: HU-001.1 | B4: Registrar usuario | C4: ✓ | D4: ✓ | E4: ✓ | F4: ✓ | G4: ✓ | H4: ✓ | I4: ⚠ | J4: ✓ | K4: ✓ | L4: =IF(COUNTA(C4:K4)=0,"",(COUNTIF(C4:K4,"✓")+COUNTIF(C4:K4,"⚠")*0.5)/9) -> 0.94444444 | M4: =IF(L4="","",IF(L4>=0.9,"CUMPLE",IF(L4>=0.6,"CUMPLE PARCIAL","NO CUMPLE"))) -> CUMPLE | N4: Existe una inconsistencia entre la descripción (rol asignado) y la regla de negocio (rol por defecto Cliente). Debe unificarse.
A5: HU-001.2 | B5: Verificar correo electrónico | C5: ✓ | D5: ✓ | E5: ✓ | F5: ✓ | G5: ✓ | H5: ✓ | I5: ✓ | J5: ✓ | K5: ✓ | L5: =IF(COUNTA(C5:K5)=0,"",(COUNTIF(C5:K5,"✓")+COUNTIF(C5:K5,"⚠")*0.5)/9) -> 1 | M5: =IF(L5="","",IF(L5>=0.9,"CUMPLE",IF(L5>=0.6,"CUMPLE PARCIAL","NO CUMPLE"))) -> CUMPLE
A6: HU-001.3 | B6: Reenviar código de verificación | C6: ✓ | D6: ✓ | E6: ✓ | F6: ✓ | G6: ✓ | H6: ✓ | I6: ⚠ | J6: ✓ | K6: ✓ | L6: =IF(COUNTA(C6:K6)=0,"",(COUNTIF(C6:K6,"✓")+COUNTIF(C6:K6,"⚠")*0.5)/9) -> 0.94444444 | M6: =IF(L6="","",IF(L6>=0.9,"CUMPLE",IF(L6>=0.6,"CUMPLE PARCIAL","NO CUMPLE"))) -> CUMPLE | N6: No se especifica si existe un límite o restricción para el reenvío de códigos.
A7: HU-001.4 | B7: Inicar sesión | C7: ✓ | D7: ✓ | E7: ✓ | F7: ✓ | G7: ✓ | H7: ✓ | I7: ✓ | J7: ✓ | K7: ✓ | L7: =IF(COUNTA(C7:K7)=0,"",(COUNTIF(C7:K7,"✓")+COUNTIF(C7:K7,"⚠")*0.5)/9) -> 1 | M7: =IF(L7="","",IF(L7>=0.9,"CUMPLE",IF(L7>=0.6,"CUMPLE PARCIAL","NO CUMPLE"))) -> CUMPLE
A8: HU-001.5 | B8: Doble factor | C8: ✓ | D8: ✓ | E8: ✓ | F8: ✓ | G8: ✓ | H8: ✓ | I8: ⚠ | J8: ✓ | K8: ✓ | L8: =IF(COUNTA(C8:K8)=0,"",(COUNTIF(C8:K8,"✓")+COUNTIF(C8:K8,"⚠")*0.5)/9) -> 0.94444444 | M8: =IF(L8="","",IF(L8>=0.9,"CUMPLE",IF(L8>=0.6,"CUMPLE PARCIAL","NO CUMPLE"))) -> CUMPLE
A9: HU-001.6 | B9: Verificar código de doble factor(2FA) | C9: ✓ | D9: ✓ | E9: ✓ | F9: ✓ | G9: ✓ | H9: ✓ | I9: ✓ | J9: ✓ | K9: ✓ | L9: =IF(COUNTA(C9:K9)=0,"",(COUNTIF(C9:K9,"✓")+COUNTIF(C9:K9,"⚠")*0.5)/9) -> 1 | M9: =IF(L9="","",IF(L9>=0.9,"CUMPLE",IF(L9>=0.6,"CUMPLE PARCIAL","NO CUMPLE"))) -> CUMPLE
A10: HU-001.7 | B10: Solicitar recuperación de contraseña | C10: ✓ | D10: ✓ | E10: ✓ | F10: ✓ | G10: ✓ | H10: ✓ | I10: ⚠ | J10: ✓ | K10: ✓ | L10: =IF(COUNTA(C10:K10)=0,"",(COUNTIF(C10:K10,"✓")+COUNTIF(C10:K10,"⚠")*0.5)/9) -> 0.94444444 | M10: =IF(L10="","",IF(L10>=0.9,"CUMPLE",IF(L10>=0.6,"CUMPLE PARCIAL","NO CUMPLE"))) -> CUMPLE | N10: Conviene indicar que se muestra un mensaje genérico por seguridad.
A11: HU-001.8 | B11: Restablecer contraseña | C11: ✓ | D11: ✓ | E11: ✓ | F11: ✓ | G11: ✓ | H11: ✓ | I11: ⚠ | J11: ✓ | K11: ✓ | L11: =IF(COUNTA(C11:K11)=0,"",(COUNTIF(C11:K11,"✓")+COUNTIF(C11:K11,"⚠")*0.5)/9) -> 0.94444444 | M11: =IF(L11="","",IF(L11>=0.9,"CUMPLE",IF(L11>=0.6,"CUMPLE PARCIAL","NO CUMPLE"))) -> CUMPLE | N11: La política de contraseña no es consistente con HU-001.1 ("mínimo 8 caracteres" vs. "más de 8 caracteres"
A12: HU-001.9 | B12: Cerrar sesión | C12: ✓ | D12: ✓ | E12: ✓ | F12: ✓ | G12: ✓ | H12: ✓ | I12: ✓ | J12: ✓ | K12: ✓ | L12: =IF(COUNTA(C12:K12)=0,"",(COUNTIF(C12:K12,"✓")+COUNTIF(C12:K12,"⚠")*0.5)/9) -> 1 | M12: =IF(L12="","",IF(L12>=0.9,"CUMPLE",IF(L12>=0.6,"CUMPLE PARCIAL","NO CUMPLE"))) -> CUMPLE
B13: RF-002
A14: HU-002.1 | B14: Registrar usuario | C14: ✓ | D14: ✓ | E14: ✓ | F14: ✓ | G14: ✓ | H14: ✓ | I14: ⚠ | J14: ⚠ | K14: ✓ | L14: =IF(COUNTA(D14:J14)=0,"",(COUNTIF(D14:J14,"✓")+COUNTIF(D14:J14,"⚠")*0.5)/7) -> 0.85714286 | M14: =IF(L14="","",IF(L14>=0.9,"CUMPLE",IF(L14>=0.6,"CUMPLE PARCIAL","NO CUMPLE"))) -> CUMPLE PARCIAL | N14: Inconcistencia con RN-006
A15: HU-002.2 | B15: Consultar usuario | C15: ✓ | D15: ✓ | E15: ✓ | F15: ✓ | G15: ✓ | H15: ✓ | I15: ✓ | J15: ✓ | K15: ✓ | L15: =IF(COUNTA(D15:J15)=0,"",(COUNTIF(D15:J15,"✓")+COUNTIF(D15:J15,"⚠")*0.5)/7) -> 1 | M15: =IF(L15="","",IF(L15>=0.9,"CUMPLE",IF(L15>=0.6,"CUMPLE PARCIAL","NO CUMPLE"))) -> CUMPLE
A16: HU-002.3 | B16: Actualizar usuario | C16: ✓ | D16: ✓ | E16: ✓ | F16: ✓ | G16: ✓ | H16: ✓ | I16: ⚠ | J16: ⚠ | K16: ✓ | L16: =IF(COUNTA(D16:J16)=0,"",(COUNTIF(D16:J16,"✓")+COUNTIF(D16:J16,"⚠")*0.5)/7) -> 0.85714286 | M16: =IF(L16="","",IF(L16>=0.9,"CUMPLE",IF(L16>=0.6,"CUMPLE PARCIAL","NO CUMPLE"))) -> CUMPLE PARCIAL | N16: Los datos de entrada no cuadran con la RF-007
A17: HU-002.4 | B17: Eliminar usuario | C17: ✓ | D17: ✓ | E17: ✓ | F17: ✓ | G17: ✓ | H17: ✓ | I17: ⚠ | J17: ⚠ | K17: ✓ | L17: =IF(COUNTA(D17:J17)=0,"",(COUNTIF(D17:J17,"✓")+COUNTIF(D17:J17,"⚠")*0.5)/7) -> 0.85714286 | M17: =IF(L17="","",IF(L17>=0.9,"CUMPLE",IF(L17>=0.6,"CUMPLE PARCIAL","NO CUMPLE"))) -> CUMPLE PARCIAL | N17: CA-001 esta mal redactado y el 005 esta duplicado
B18: RF-003
A19: HU-003.1 | B19: Consultar Catálogo de Productos | C19: ✓ | D19: ✓ | E19: ✓ | F19: ✓ | G19: ✓ | H19: ✓ | I19: ✓ | J19: ✓ | K19: ✓ | L19: =IF(COUNTA(C19:J19)=0,"",(COUNTIF(C19:J19,"✓")+COUNTIF(C19:J19,"⚠")*0.5)/8) -> 1 | M19: =IF(L19="","",IF(L19>=0.9,"CUMPLE",IF(L19>=0.6,"CUMPLE PARCIAL","NO CUMPLE"))) -> CUMPLE
A20: HU-003.2 | B20: Filtrado y Búsqueda de Productos | C20: ✓ | D20: ✓ | E20: ✓ | F20: ✓ | G20: ✓ | H20: ✓ | I20: ✓ | J20: ✓ | K20: ✓ | L20: =IF(COUNTA(C20:J20)=0,"",(COUNTIF(C20:J20,"✓")+COUNTIF(C20:J20,"⚠")*0.5)/8) -> 1 | M20: =IF(L20="","",IF(L20>=0.9,"CUMPLE",IF(L20>=0.6,"CUMPLE PARCIAL","NO CUMPLE"))) -> CUMPLE
A21: HU-003.3 | B21: Agregar Producto al Carrito. | C21: ✓ | D21: ✓ | E21: ✓ | F21: ✓ | G21: ✓ | H21: ✓ | I21: ✓ | J21: ✓ | K21: ✓ | L21: =IF(COUNTA(C21:J21)=0,"",(COUNTIF(C21:J21,"✓")+COUNTIF(C21:J21,"⚠")*0.5)/8) -> 1 | M21: =IF(L21="","",IF(L21>=0.9,"CUMPLE",IF(L21>=0.6,"CUMPLE PARCIAL","NO CUMPLE"))) -> CUMPLE
A22: HU-003.4 | B22: Visualizar Carrito de Compras | C22: ✓ | D22: ✓ | E22: ✓ | F22: ✓ | G22: ✓ | H22: ✓ | I22: ✓ | J22: ✓ | K22: ✓ | L22: =IF(COUNTA(C22:J22)=0,"",(COUNTIF(C22:J22,"✓")+COUNTIF(C22:J22,"⚠")*0.5)/8) -> 1 | M22: =IF(L22="","",IF(L22>=0.9,"CUMPLE",IF(L22>=0.6,"CUMPLE PARCIAL","NO CUMPLE"))) -> CUMPLE
A23: HU-003.5 | B23: Modificar Cantidades en Carrito | C23: ✓ | D23: ✓ | E23: ✓ | F23: ✓ | G23: ✓ | H23: ✓ | I23: ✓ | J23: ✓ | K23: ✓ | L23: =IF(COUNTA(C23:J23)=0,"",(COUNTIF(C23:J23,"✓")+COUNTIF(C23:J23,"⚠")*0.5)/8) -> 1 | M23: =IF(L23="","",IF(L23>=0.9,"CUMPLE",IF(L23>=0.6,"CUMPLE PARCIAL","NO CUMPLE"))) -> CUMPLE
A24: HU-003.6 | B24: Seleccionar Método de Pago | C24: ✓ | D24: ✓ | E24: ✓ | F24: ✓ | G24: ✓ | H24: ✓ | I24: ✓ | J24: ✓ | K24: ✓ | L24: =IF(COUNTA(C24:J24)=0,"",(COUNTIF(C24:J24,"✓")+COUNTIF(C24:J24,"⚠")*0.5)/8) -> 1 | M24: =IF(L24="","",IF(L24>=0.9,"CUMPLE",IF(L24>=0.6,"CUMPLE PARCIAL","NO CUMPLE"))) -> CUMPLE
A25: HU-003.7 | B25: Confirmar Compra | C25: ✓ | D25: ✓ | E25: ✓ | F25: ✓ | G25: ✓ | H25: ✓ | I25: ✓ | J25: ✓ | K25: ✓ | L25: =IF(COUNTA(C25:J25)=0,"",(COUNTIF(C25:J25,"✓")+COUNTIF(C25:J25,"⚠")*0.5)/8) -> 1 | M25: =IF(L25="","",IF(L25>=0.9,"CUMPLE",IF(L25>=0.6,"CUMPLE PARCIAL","NO CUMPLE"))) -> CUMPLE
A26: HU-003.8 | B26: Comprobante de Venta | C26: ✓ | D26: ✓ | E26: ✓ | F26: ✓ | G26: ✓ | H26: ✓ | I26: ✓ | J26: ✓ | K26: ✓ | L26: =IF(COUNTA(C26:J26)=0,"",(COUNTIF(C26:J26,"✓")+COUNTIF(C26:J26,"⚠")*0.5)/8) -> 1 | M26: =IF(L26="","",IF(L26>=0.9,"CUMPLE",IF(L26>=0.6,"CUMPLE PARCIAL","NO CUMPLE"))) -> CUMPLE
A28: HU-004.1 | B28: Registrar Producto | C28: ✓ | D28: ✓ | E28: ✓ | F28: ✓ | G28: ✓ | H28: ✓ | I28: ✓ | J28: ✓ | K28: ✓ | L28: =IF(COUNTA(C28:J28)=0,"",(COUNTIF(C28:J28,"✓")+COUNTIF(C28:J28,"⚠")*0.5)/8) -> 1 | M28: =IF(L28="","",IF(L28>=0.9,"CUMPLE",IF(L28>=0.6,"CUMPLE PARCIAL","NO CUMPLE"))) -> CUMPLE
A29: HU-004.2 | B29: Listar / consultar productos | C29: ✓ | D29: ✓ | E29: ✓ | F29: ✓ | G29: ✓ | H29: ✓ | I29: ✓ | J29: ✓ | K29: ✓ | L29: =IF(COUNTA(C29:J29)=0,"",(COUNTIF(C29:J29,"✓")+COUNTIF(C29:J29,"⚠")*0.5)/8) -> 1 | M29: =IF(L29="","",IF(L29>=0.9,"CUMPLE",IF(L29>=0.6,"CUMPLE PARCIAL","NO CUMPLE"))) -> CUMPLE
A30: HU-004.3 | B30: Actualizar producto | C30: ✓ | D30: ✓ | E30: ✓ | F30: ✓ | G30: ✓ | H30: ✓ | I30: ✓ | J30: ✓ | K30: ✓ | L30: =IF(COUNTA(C30:J30)=0,"",(COUNTIF(C30:J30,"✓")+COUNTIF(C30:J30,"⚠")*0.5)/8) -> 1 | M30: =IF(L30="","",IF(L30>=0.9,"CUMPLE",IF(L30>=0.6,"CUMPLE PARCIAL","NO CUMPLE"))) -> CUMPLE
A31: HU-004.4 | B31: Deshabilitar producto | C31: ✓ | D31: ✓ | E31: ✓ | F31: ✓ | G31: ✓ | H31: ✓ | I31: ✓ | J31: ✓ | K31: ✓ | L31: =IF(COUNTA(C31:J31)=0,"",(COUNTIF(C31:J31,"✓")+COUNTIF(C31:J31,"⚠")*0.5)/8) -> 1 | M31: =IF(L31="","",IF(L31>=0.9,"CUMPLE",IF(L31>=0.6,"CUMPLE PARCIAL","NO CUMPLE"))) -> CUMPLE
B32: Registro de movimiento
A33: HU-005.1 | B33: Reporte de Ventas por Mes | C33: ✓ | D33: ✓ | E33: ✓ | F33: ✓ | G33: ✓ | H33: ✓ | I33: ✓ | J33: ✓ | K33: ✓ | L33: =IF(COUNTA(C33:J33)=0,"",(COUNTIF(C33:J33,"✓")+COUNTIF(C33:J33,"⚠")*0.5)/8) -> 1 | M33: =IF(L33="","",IF(L33>=0.9,"CUMPLE",IF(L33>=0.6,"CUMPLE PARCIAL","NO CUMPLE"))) -> CUMPLE
A34: HU-005.2 | B34: Top productos | C34: ✓ | D34: ✓ | E34: ✓ | F34: ✓ | G34: ✓ | H34: ✓ | I34: ✓ | J34: ✓ | K34: ✓
A35: HU-005.3 | B35: Resumen general | C35: ✓ | D35: ✓ | E35: ✓ | F35: ✓ | G35: ✓ | H35: ✓ | I35: ✓ | J35: ✓ | K35: ✓
A36: HU-005.4 | B36: Exportar PDF | C36: ✓ | D36: ✓ | E36: ✓ | F36: ✓ | G36: ✓ | H36: ✓ | I36: ✓ | J36: ✓ | K36: ✓
B37: RF-006
A38: HU-006.1 | B38: Registro de Movimiento | C38: ✓ | D38: ✓ | E38: ✓ | F38: ✓ | G38: ✓ | H38: ✓ | I38: ✓ | J38: ✓ | K38: ✓ | L38: =IF(COUNTA(C38:J38)=0,"",(COUNTIF(C38:J38,"✓")+COUNTIF(C38:J38,"⚠")*0.5)/8) -> 1 | M38: =IF(L38="","",IF(L38>=0.9,"CUMPLE",IF(L38>=0.6,"CUMPLE PARCIAL","NO CUMPLE"))) -> CUMPLE
A39: HU-006.2 | B39: Notificación al Administrador por Bajo Stock | C39: ✓ | D39: ✓ | E39: ✓ | F39: ✓ | G39: ✓ | H39: ✓ | I39: ✓ | J39: ✓ | K39: ✓ | L39: =IF(COUNTA(C39:J39)=0,"",(COUNTIF(C39:J39,"✓")+COUNTIF(C39:J39,"⚠")*0.5)/8) -> 1 | M39: =IF(L39="","",IF(L39>=0.9,"CUMPLE",IF(L39>=0.6,"CUMPLE PARCIAL","NO CUMPLE"))) -> CUMPLE
B40: RF-007
A41: HU-007.1 | B41: Listar proveedores | C41: ✓ | D41: ✓ | E41: ✓ | F41: ✓ | G41: ✓ | H41: ✓ | I41: ✓ | J41: ✓ | K41: ✓ | L41: =IF(COUNTA(C41:J41)=0,"",(COUNTIF(C41:J41,"✓")+COUNTIF(C41:J41,"⚠")*0.5)/8) -> 1 | M41: =IF(L41="","",IF(L41>=0.9,"CUMPLE",IF(L41>=0.6,"CUMPLE PARCIAL","NO CUMPLE"))) -> CUMPLE
...

Sheet Resumen
A1: RESUMEN — PANEL DE CUMPLIMIENTO QA
A3: Componente evaluado | B3: Total ítems | C3: Cumple | D3: Cumple Parcial | E3: No Cumple
A4: Requisitos Funcionales (RF) | B4: 36 | C4: =COUNTIF('Checklist RF'!P4:P45,"CUMPLE") -> 36 | D4: =COUNTIF('Checklist RF'!P4:P45,"CUMPLE PARCIAL") -> 0 | E4: =COUNTIF('Checklist RF'!P4:P45,"NO CUMPLE") -> 0
A5: Casos de Uso Extendido (CU) | B5: 35 | C5: =COUNTIF('Checklist CU'!L4:L44,"CUMPLE") -> 33 | D5: =COUNTIF('Checklist CU'!L4:L44,"CUMPLE PARCIAL") -> 2 | E5: =COUNTIF('Checklist CU'!L4:L44,"NO CUMPLE") -> 0
A6: Historias de Usuario (HU) | B6: 35 | C6: =COUNTIF('Checklist HU'!M3:M50,"CUMPLE") -> 29 | D6: =COUNTIF('Checklist HU'!M3:M50,"CUMPLE PARCIAL") -> 3 | E6: =COUNTIF('Checklist HU'!M3:M50,"NO CUMPLE") -> 0
A8: Nota: este panel se actualiza automáticamente según lo diligenciado en cada hoja de checklist.
