Workbook

Sheet Dashboard
A1: DASHBOARD EJECUTIVO DE COBERTURA Y TRAZABILIDAD DE PRUEBAS
A2: Proyecto: | B2: Mercapleno - Sistema de Gestion de Ventas e Inventario | G2: Ultima actualizacion: | I2: =TODAY() -> 46243
A4: INDICADORES CLAVE (KPI)
B5: Total de Requisitos Funcionales | C5: =COUNTA('Cobertura de Requisitos'!A4:A149) -> 35 | E5: Total de Pruebas Unitarias | F5: =SUM('Cobertura de Requisitos'!G4:G149) -> 8 | H5: Casos Pendientes (Ejecucion) | I5: =E13 -> 5 | K5: Estado de Requisitos
B6: RF con Cobertura de Pruebas | C6: =COUNTIF('Cobertura de Requisitos'!J4:J149,"Completo")+COUNTIF('Cobertura de Requisitos'!J4:J149,"Parcial") -> 15 | E6: Total de Pruebas de Integracion | F6: =SUM('Cobertura de Requisitos'!H4:H149) -> 0 | H6: Cobertura General (%) | I6: =AVERAGE('Cobertura de Requisitos'!I4:I149) -> 0.12142857 | K6: Completo | L6: =COUNTIF('Cobertura de Requisitos'!J4:J149,"Completo") -> 0
B7: RF Pendientes | C7: =COUNTIF('Cobertura de Requisitos'!J4:J149,"Pendiente") -> 20 | E7: Casos Aprobados | F7: =B13 -> 46 | H7: Cobertura Manual (%) | I7: =IFERROR(COUNTIFS('Cobertura de Requisitos'!F4:F149,">0")/$C$5,0) -> 0.028571429 | K7: Parcial | L7: =COUNTIF('Cobertura de Requisitos'!J4:J149,"Parcial") -> 15
B8: Total de Casos Funcionales | C8: =SUM('Cobertura de Requisitos'!E4:E149) -> 86 | E8: Casos Fallidos | F8: =C13 -> 6 | H8: Cobertura Unitaria (%) | I8: =IFERROR(COUNTIFS('Cobertura de Requisitos'!G4:G149,">0")/$C$5,0) -> 0.028571429 | K8: Pendiente | L8: =COUNTIF('Cobertura de Requisitos'!J4:J149,"Pendiente") -> 20
B9: Total de Pruebas Manuales Ejecutadas | C9: =SUM('Cobertura de Requisitos'!F4:F149) -> 8 | E9: Casos Bloqueados | F9: =D13 -> 3 | H9: Cobertura de Integracion (%) | I9: =IFERROR(COUNTIFS('Cobertura de Requisitos'!H4:H149,">0")/$C$5,0) -> 0
K10: Pruebas por Tipo
A11: RESUMEN DE EJECUCION (ENTRADA MANUAL - tomar de Ejecucion de Pruebas / Registro de Defectos) | K11: Manual | L11: =C9 -> 8
B12: Casos Aprobados | C12: Casos Fallidos | D12: Casos Bloqueados | E12: Casos Pendientes | F12: Defectos Encontrados | G12: Defectos Corregidos | K12: Unitaria | L12: =F5 -> 8
B13: 46 | C13: 6 | D13: 3 | E13: 5 | F13: 14 | G13: 11 | K13: Integracion | L13: =F6 -> 0
A15: GRAFICOS DE COBERTURA Y CALIDAD
K16: Aprobados | L16: =B13 -> 46
K17: Fallidos | L17: =C13 -> 6
K19: Datos base para graficos. No editar directamente.

Sheet Matriz de Trazabilidad
A1: MATRIZ DE TRAZABILIDAD: RF -> CASOS -> PRUEBAS -> ESTADO
A2: Permite identificar de un vistazo si un requisito carece de algun tipo de prueba.
A3: RF | B3: Nombre del Requisito | C3: Casos de Prueba | D3: Pruebas Manuales | E3: Pruebas Unitarias | F3: Pruebas de Integracion | G3: Estado Final | H3: Observaciones (Vacios Detectados)
A4: =IF('Cobertura de Requisitos'!A4="","",'Cobertura de Requisitos'!A4) -> RF-001 | B4: =IF($A4="","",'Cobertura de Requisitos'!B4) -> Registrar usuario | C4: =IF($A4="","",IF('Cobertura de Requisitos'!E4>0,"Si","No")) -> Si | D4: =IF($A4="","",IF('Cobertura de Requisitos'!F4>0,"Si","No")) -> Si | E4: =IF($A4="","",IF('Cobertura de Requisitos'!G4>0,"Si","No")) -> Si | F4: =IF($A4="","",IF('Cobertura de Requisitos'!H4>0,"Si","No")) -> No | G4: =IF($A4="","",'Cobertura de Requisitos'!J4) -> Parcial | H4: =IF($A4="","",IF('Cobertura de Requisitos'!J4="Pendiente","Sin cobertura - requiere pruebas",IF('Cobertura de Requisitos'!J4="Parcial","Cobertura incompleta - revisar pruebas faltantes","Cobertura completa"))) -> Cobertura incompleta - revisar pruebas faltantes
A5: =IF('Cobertura de Requisitos'!A5="","",'Cobertura de Requisitos'!A5) -> RF-002 | B5: =IF($A5="","",'Cobertura de Requisitos'!B5) -> Verificar correo electrónico | C5: =IF($A5="","",IF('Cobertura de Requisitos'!E5>0,"Si","No")) -> Si | D5: =IF($A5="","",IF('Cobertura de Requisitos'!F5>0,"Si","No")) -> No | E5: =IF($A5="","",IF('Cobertura de Requisitos'!G5>0,"Si","No")) -> No | F5: =IF($A5="","",IF('Cobertura de Requisitos'!H5>0,"Si","No")) -> No | G5: =IF($A5="","",'Cobertura de Requisitos'!J5) -> Parcial | H5: =IF($A5="","",IF('Cobertura de Requisitos'!J5="Pendiente","Sin cobertura - requiere pruebas",IF('Cobertura de Requisitos'!J5="Parcial","Cobertura incompleta - revisar pruebas faltantes","Cobertura completa"))) -> Cobertura incompleta - revisar pruebas faltantes
A6: =IF('Cobertura de Requisitos'!A6="","",'Cobertura de Requisitos'!A6) -> RF-003 | B6: =IF($A6="","",'Cobertura de Requisitos'!B6) -> Reenviar código de verificación | C6: =IF($A6="","",IF('Cobertura de Requisitos'!E6>0,"Si","No")) -> Si | D6: =IF($A6="","",IF('Cobertura de Requisitos'!F6>0,"Si","No")) -> No | E6: =IF($A6="","",IF('Cobertura de Requisitos'!G6>0,"Si","No")) -> No | F6: =IF($A6="","",IF('Cobertura de Requisitos'!H6>0,"Si","No")) -> No | G6: =IF($A6="","",'Cobertura de Requisitos'!J6) -> Parcial | H6: =IF($A6="","",IF('Cobertura de Requisitos'!J6="Pendiente","Sin cobertura - requiere pruebas",IF('Cobertura de Requisitos'!J6="Parcial","Cobertura incompleta - revisar pruebas faltantes","Cobertura completa"))) -> Cobertura incompleta - revisar pruebas faltantes
A7: =IF('Cobertura de Requisitos'!A7="","",'Cobertura de Requisitos'!A7) -> RF-004 | B7: =IF($A7="","",'Cobertura de Requisitos'!B7) -> Inicar sesión | C7: =IF($A7="","",IF('Cobertura de Requisitos'!E7>0,"Si","No")) -> Si | D7: =IF($A7="","",IF('Cobertura de Requisitos'!F7>0,"Si","No")) -> No | E7: =IF($A7="","",IF('Cobertura de Requisitos'!G7>0,"Si","No")) -> No | F7: =IF($A7="","",IF('Cobertura de Requisitos'!H7>0,"Si","No")) -> No | G7: =IF($A7="","",'Cobertura de Requisitos'!J7) -> Parcial | H7: =IF($A7="","",IF('Cobertura de Requisitos'!J7="Pendiente","Sin cobertura - requiere pruebas",IF('Cobertura de Requisitos'!J7="Parcial","Cobertura incompleta - revisar pruebas faltantes","Cobertura completa"))) -> Cobertura incompleta - revisar pruebas faltantes
A8: =IF('Cobertura de Requisitos'!A8="","",'Cobertura de Requisitos'!A8) -> RF-005 | B8: =IF($A8="","",'Cobertura de Requisitos'!B8) -> Doble factor | C8: =IF($A8="","",IF('Cobertura de Requisitos'!E8>0,"Si","No")) -> Si | D8: =IF($A8="","",IF('Cobertura de Requisitos'!F8>0,"Si","No")) -> No | E8: =IF($A8="","",IF('Cobertura de Requisitos'!G8>0,"Si","No")) -> No | F8: =IF($A8="","",IF('Cobertura de Requisitos'!H8>0,"Si","No")) -> No | G8: =IF($A8="","",'Cobertura de Requisitos'!J8) -> Parcial | H8: =IF($A8="","",IF('Cobertura de Requisitos'!J8="Pendiente","Sin cobertura - requiere pruebas",IF('Cobertura de Requisitos'!J8="Parcial","Cobertura incompleta - revisar pruebas faltantes","Cobertura completa"))) -> Cobertura incompleta - revisar pruebas faltantes
A9: =IF('Cobertura de Requisitos'!A9="","",'Cobertura de Requisitos'!A9) -> RF-006 | B9: =IF($A9="","",'Cobertura de Requisitos'!B9) -> Verificar código de doble factor(2FA) | C9: =IF($A9="","",IF('Cobertura de Requisitos'!E9>0,"Si","No")) -> Si | D9: =IF($A9="","",IF('Cobertura de Requisitos'!F9>0,"Si","No")) -> No | E9: =IF($A9="","",IF('Cobertura de Requisitos'!G9>0,"Si","No")) -> No | F9: =IF($A9="","",IF('Cobertura de Requisitos'!H9>0,"Si","No")) -> No | G9: =IF($A9="","",'Cobertura de Requisitos'!J9) -> Parcial | H9: =IF($A9="","",IF('Cobertura de Requisitos'!J9="Pendiente","Sin cobertura - requiere pruebas",IF('Cobertura de Requisitos'!J9="Parcial","Cobertura incompleta - revisar pruebas faltantes","Cobertura completa"))) -> Cobertura incompleta - revisar pruebas faltantes
A10: =IF('Cobertura de Requisitos'!A10="","",'Cobertura de Requisitos'!A10) -> RF-007 | B10: =IF($A10="","",'Cobertura de Requisitos'!B10) -> Solicitar recuperación de contraseña | C10: =IF($A10="","",IF('Cobertura de Requisitos'!E10>0,"Si","No")) -> Si | D10: =IF($A10="","",IF('Cobertura de Requisitos'!F10>0,"Si","No")) -> No | E10: =IF($A10="","",IF('Cobertura de Requisitos'!G10>0,"Si","No")) -> No | F10: =IF($A10="","",IF('Cobertura de Requisitos'!H10>0,"Si","No")) -> No | G10: =IF($A10="","",'Cobertura de Requisitos'!J10) -> Parcial | H10: =IF($A10="","",IF('Cobertura de Requisitos'!J10="Pendiente","Sin cobertura - requiere pruebas",IF('Cobertura de Requisitos'!J10="Parcial","Cobertura incompleta - revisar pruebas faltantes","Cobertura completa"))) -> Cobertura incompleta - revisar pruebas faltantes
A11: =IF('Cobertura de Requisitos'!A11="","",'Cobertura de Requisitos'!A11) -> RF-008 | B11: =IF($A11="","",'Cobertura de Requisitos'!B11) -> Restablecer contraseña | C11: =IF($A11="","",IF('Cobertura de Requisitos'!E11>0,"Si","No")) -> Si | D11: =IF($A11="","",IF('Cobertura de Requisitos'!F11>0,"Si","No")) -> No | E11: =IF($A11="","",IF('Cobertura de Requisitos'!G11>0,"Si","No")) -> No | F11: =IF($A11="","",IF('Cobertura de Requisitos'!H11>0,"Si","No")) -> No | G11: =IF($A11="","",'Cobertura de Requisitos'!J11) -> Parcial | H11: =IF($A11="","",IF('Cobertura de Requisitos'!J11="Pendiente","Sin cobertura - requiere pruebas",IF('Cobertura de Requisitos'!J11="Parcial","Cobertura incompleta - revisar pruebas faltantes","Cobertura completa"))) -> Cobertura incompleta - revisar pruebas faltantes
A12: =IF('Cobertura de Requisitos'!A12="","",'Cobertura de Requisitos'!A12) -> RF-009 | B12: =IF($A12="","",'Cobertura de Requisitos'!B12) -> Cerrar sesión | C12: =IF($A12="","",IF('Cobertura de Requisitos'!E12>0,"Si","No")) -> Si | D12: =IF($A12="","",IF('Cobertura de Requisitos'!F12>0,"Si","No")) -> No | E12: =IF($A12="","",IF('Cobertura de Requisitos'!G12>0,"Si","No")) -> No | F12: =IF($A12="","",IF('Cobertura de Requisitos'!H12>0,"Si","No")) -> No | G12: =IF($A12="","",'Cobertura de Requisitos'!J12) -> Parcial | H12: =IF($A12="","",IF('Cobertura de Requisitos'!J12="Pendiente","Sin cobertura - requiere pruebas",IF('Cobertura de Requisitos'!J12="Parcial","Cobertura incompleta - revisar pruebas faltantes","Cobertura completa"))) -> Cobertura incompleta - revisar pruebas faltantes
A13: =IF('Cobertura de Requisitos'!A13="","",'Cobertura de Requisitos'!A13) -> RF-010 | B13: =IF($A13="","",'Cobertura de Requisitos'!B13) -> Registrar usuario | C13: =IF($A13="","",IF('Cobertura de Requisitos'!E13>0,"Si","No")) -> Si | D13: =IF($A13="","",IF('Cobertura de Requisitos'!F13>0,"Si","No")) -> No | E13: =IF($A13="","",IF('Cobertura de Requisitos'!G13>0,"Si","No")) -> No | F13: =IF($A13="","",IF('Cobertura de Requisitos'!H13>0,"Si","No")) -> No | G13: =IF($A13="","",'Cobertura de Requisitos'!J13) -> Parcial | H13: =IF($A13="","",IF('Cobertura de Requisitos'!J13="Pendiente","Sin cobertura - requiere pruebas",IF('Cobertura de Requisitos'!J13="Parcial","Cobertura incompleta - revisar pruebas faltantes","Cobertura completa"))) -> Cobertura incompleta - revisar pruebas faltantes
A14: =IF('Cobertura de Requisitos'!A14="","",'Cobertura de Requisitos'!A14) -> RF-011 | B14: =IF($A14="","",'Cobertura de Requisitos'!B14) -> Consultar usuario | C14: =IF($A14="","",IF('Cobertura de Requisitos'!E14>0,"Si","No")) -> Si | D14: =IF($A14="","",IF('Cobertura de Requisitos'!F14>0,"Si","No")) -> No | E14: =IF($A14="","",IF('Cobertura de Requisitos'!G14>0,"Si","No")) -> No | F14: =IF($A14="","",IF('Cobertura de Requisitos'!H14>0,"Si","No")) -> No | G14: =IF($A14="","",'Cobertura de Requisitos'!J14) -> Parcial | H14: =IF($A14="","",IF('Cobertura de Requisitos'!J14="Pendiente","Sin cobertura - requiere pruebas",IF('Cobertura de Requisitos'!J14="Parcial","Cobertura incompleta - revisar pruebas faltantes","Cobertura completa"))) -> Cobertura incompleta - revisar pruebas faltantes
A15: =IF('Cobertura de Requisitos'!A15="","",'Cobertura de Requisitos'!A15) -> RF-012 | B15: =IF($A15="","",'Cobertura de Requisitos'!B15) -> Actualizar usuario | C15: =IF($A15="","",IF('Cobertura de Requisitos'!E15>0,"Si","No")) -> Si | D15: =IF($A15="","",IF('Cobertura de Requisitos'!F15>0,"Si","No")) -> No | E15: =IF($A15="","",IF('Cobertura de Requisitos'!G15>0,"Si","No")) -> No | F15: =IF($A15="","",IF('Cobertura de Requisitos'!H15>0,"Si","No")) -> No | G15: =IF($A15="","",'Cobertura de Requisitos'!J15) -> Parcial | H15: =IF($A15="","",IF('Cobertura de Requisitos'!J15="Pendiente","Sin cobertura - requiere pruebas",IF('Cobertura de Requisitos'!J15="Parcial","Cobertura incompleta - revisar pruebas faltantes","Cobertura completa"))) -> Cobertura incompleta - revisar pruebas faltantes
... A149: =IF('Cobertura de Requisitos'!A149="","",'Cobertura de Requisitos'!A149) | B149: =IF($A149="","",'Cobertura de Requisitos'!B149) | C149: =IF($A149="","",IF('Cobertura de Requisitos'!E149>0,"Si","No")) | D149: =IF($A149="","",IF('Cobertura de Requisitos'!F149>0,"Si","No")) | E149: =IF($A149="","",IF('Cobertura de Requisitos'!G149>0,"Si","No")) | F149: =IF($A149="","",IF('Cobertura de Requisitos'!H149>0,"Si","No")) | G149: =IF($A149="","",'Cobertura de Requisitos'!J149) | H149: =IF($A149="","",IF('Cobertura de Requisitos'!J149="Pendiente","Sin cobertura - requiere pruebas",IF('Cobertura de Requisitos'!J149="Parcial","Cobertura incompleta - revisar pruebas faltantes","Cobertura completa")))

Sheet Cobertura de Requisitos
A1: MATRIZ DE COBERTURA DE REQUISITOS FUNCIONALES
A2: Nota: los conteos de Casos / Pruebas Manuales / Unitarias / Integracion NO tienen relacion 1:1. Un caso funcional puede derivar en multiples pruebas tecnicas.
A3: RF | B3: Nombre del Requisito | C3: Modulo | D3: Prioridad | E3: Casos Funcionales Disenados | F3: Pruebas Manuales Ejecutadas | G3: Pruebas Unitarias | H3: Pruebas de Integracion | I3: Cobertura (%) | J3: Estado
A4: RF-001 | B4: Registrar usuario | C4: Autenticacion | D4: Alta | E4: 8 | F4: 8 | G4: 8 | H4: 0 | I4: =IF($A4="","",(IF(E4>0,1,0)+IF(F4>0,1,0)+IF(G4>0,1,0)+IF(H4>0,1,0))/4) -> 0.75 | J4: =IF($A4="","",IF(I4=1,"Completo",IF(I4=0,"Pendiente","Parcial"))) -> Parcial
A5: RF-002 | B5: Verificar correo electrónico | C5: Autenticacion | D5: Alta | E5: 5 | F5: 0 | G5: 0 | H5: 0 | I5: =IF($A5="","",(IF(E5>0,1,0)+IF(F5>0,1,0)+IF(G5>0,1,0)+IF(H5>0,1,0))/4) -> 0.25 | J5: =IF($A5="","",IF(I5=1,"Completo",IF(I5=0,"Pendiente","Parcial"))) -> Parcial
A6: RF-003 | B6: Reenviar código de verificación | C6: Autenticacion | D6: Alta | E6: 6 | F6: 0 | G6: 0 | H6: 0 | I6: =IF($A6="","",(IF(E6>0,1,0)+IF(F6>0,1,0)+IF(G6>0,1,0)+IF(H6>0,1,0))/4) -> 0.25 | J6: =IF($A6="","",IF(I6=1,"Completo",IF(I6=0,"Pendiente","Parcial"))) -> Parcial
A7: RF-004 | B7: Inicar sesión | C7: Autenticacion | D7: Alta | E7: 3 | F7: 0 | G7: 0 | H7: 0 | I7: =IF($A7="","",(IF(E7>0,1,0)+IF(F7>0,1,0)+IF(G7>0,1,0)+IF(H7>0,1,0))/4) -> 0.25 | J7: =IF($A7="","",IF(I7=1,"Completo",IF(I7=0,"Pendiente","Parcial"))) -> Parcial
A8: RF-005 | B8: Doble factor | C8: Autenticacion | D8: Alta | E8: 7 | F8: 0 | G8: 0 | H8: 0 | I8: =IF($A8="","",(IF(E8>0,1,0)+IF(F8>0,1,0)+IF(G8>0,1,0)+IF(H8>0,1,0))/4) -> 0.25 | J8: =IF($A8="","",IF(I8=1,"Completo",IF(I8=0,"Pendiente","Parcial"))) -> Parcial
A9: RF-006 | B9: Verificar código de doble factor(2FA) | C9: Autenticacion | D9: Alta | E9: 9 | F9: 0 | G9: 0 | H9: 0 | I9: =IF($A9="","",(IF(E9>0,1,0)+IF(F9>0,1,0)+IF(G9>0,1,0)+IF(H9>0,1,0))/4) -> 0.25 | J9: =IF($A9="","",IF(I9=1,"Completo",IF(I9=0,"Pendiente","Parcial"))) -> Parcial
A10: RF-007 | B10: Solicitar recuperación de contraseña | C10: Autenticacion | D10: Alta | E10: 6 | F10: 0 | G10: 0 | H10: 0 | I10: =IF($A10="","",(IF(E10>0,1,0)+IF(F10>0,1,0)+IF(G10>0,1,0)+IF(H10>0,1,0))/4) -> 0.25 | J10: =IF($A10="","",IF(I10=1,"Completo",IF(I10=0,"Pendiente","Parcial"))) -> Parcial
A11: RF-008 | B11: Restablecer contraseña | C11: Autenticacion | D11: Alta | E11: 4 | F11: 0 | G11: 0 | H11: 0 | I11: =IF($A11="","",(IF(E11>0,1,0)+IF(F11>0,1,0)+IF(G11>0,1,0)+IF(H11>0,1,0))/4) -> 0.25 | J11: =IF($A11="","",IF(I11=1,"Completo",IF(I11=0,"Pendiente","Parcial"))) -> Parcial
A12: RF-009 | B12: Cerrar sesión | C12: Autenticacion | D12: Alta | E12: 10 | F12: 0 | G12: 0 | H12: 0 | I12: =IF($A12="","",(IF(E12>0,1,0)+IF(F12>0,1,0)+IF(G12>0,1,0)+IF(H12>0,1,0))/4) -> 0.25 | J12: =IF($A12="","",IF(I12=1,"Completo",IF(I12=0,"Pendiente","Parcial"))) -> Parcial
A13: RF-010 | B13: Registrar usuario | C13: Gestion de Usuarios | D13: Alta | E13: 5 | F13: 0 | G13: 0 | H13: 0 | I13: =IF($A13="","",(IF(E13>0,1,0)+IF(F13>0,1,0)+IF(G13>0,1,0)+IF(H13>0,1,0))/4) -> 0.25 | J13: =IF($A13="","",IF(I13=1,"Completo",IF(I13=0,"Pendiente","Parcial"))) -> Parcial
A14: RF-011 | B14: Consultar usuario | C14: Gestion de Usuarios | D14: Alta | E14: 7 | F14: 0 | G14: 0 | H14: 0 | I14: =IF($A14="","",(IF(E14>0,1,0)+IF(F14>0,1,0)+IF(G14>0,1,0)+IF(H14>0,1,0))/4) -> 0.25 | J14: =IF($A14="","",IF(I14=1,"Completo",IF(I14=0,"Pendiente","Parcial"))) -> Parcial
A15: RF-012 | B15: Actualizar usuario | C15: Gestion de Usuarios | D15: Alta | E15: 4 | F15: 0 | G15: 0 | H15: 0 | I15: =IF($A15="","",(IF(E15>0,1,0)+IF(F15>0,1,0)+IF(G15>0,1,0)+IF(H15>0,1,0))/4) -> 0.25 | J15: =IF($A15="","",IF(I15=1,"Completo",IF(I15=0,"Pendiente","Parcial"))) -> Parcial
... A19: RF-016 | B19: Agregar Producto al Carrito. | C19: Ventas | D19: Alta | E19: 4 | F19: 0 | G19: 0 | H19: 0 | I19: =IF($A19="","",(IF(E19>0,1,0)+IF(F19>0,1,0)+IF(G19>0,1,0)+IF(H19>0,1,0))/4) -> 0.25 | J19: =IF($A19="","",IF(I19=1,"Completo",IF(I19=0,"Pendiente","Parcial"))) -> Parcial
A20: RF-017 | B20: Visualizar Carrito de Compras | C20: Ventas | D20: Alta | F20: 0 | G20: 0 | H20: 0 | I20: =IF($A20="","",(IF(E20>0,1,0)+IF(F20>0,1,0)+IF(G20>0,1,0)+IF(H20>0,1,0))/4) -> 0 | J20: =IF($A20="","",IF(I20=1,"Completo",IF(I20=0,"Pendiente","Parcial"))) -> Pendiente
A21: RF-018 | B21: Modificar Cantidades en Carrito | C21: Ventas | D21: Media | F21: 0 | G21: 0 | H21: 0 | I21: =IF($A21="","",(IF(E21>0,1,0)+IF(F21>0,1,0)+IF(G21>0,1,0)+IF(H21>0,1,0))/4) -> 0 | J21: =IF($A21="","",IF(I21=1,"Completo",IF(I21=0,"Pendiente","Parcial"))) -> Pendiente
A22: RF-019 | B22: Seleccionar Método de Pago | C22: Ventas | D22: Media | F22: 0 | G22: 0 | H22: 0 | I22: =IF($A22="","",(IF(E22>0,1,0)+IF(F22>0,1,0)+IF(G22>0,1,0)+IF(H22>0,1,0))/4) -> 0 | J22: =IF($A22="","",IF(I22=1,"Completo",IF(I22=0,"Pendiente","Parcial"))) -> Pendiente
A23: RF-020 | B23: Confirmar Compra | C23: Ventas | D23: Alta | F23: 0 | G23: 0 | H23: 0 | I23: =IF($A23="","",(IF(E23>0,1,0)+IF(F23>0,1,0)+IF(G23>0,1,0)+IF(H23>0,1,0))/4) -> 0 | J23: =IF($A23="","",IF(I23=1,"Completo",IF(I23=0,"Pendiente","Parcial"))) -> Pendiente
A24: RF-021 | B24: Comprobante de Venta | C24: Ventas | D24: Alta | F24: 0 | G24: 0 | H24: 0 | I24: =IF($A24="","",(IF(E24>0,1,0)+IF(F24>0,1,0)+IF(G24>0,1,0)+IF(H24>0,1,0))/4) -> 0 | J24: =IF($A24="","",IF(I24=1,"Completo",IF(I24=0,"Pendiente","Parcial"))) -> Pendiente
A25: RF-022 | B25: Registrar Producto | C25: Gestión de productos | D25: Alta | F25: 0 | G25: 0 | H25: 0 | I25: =IF($A25="","",(IF(E25>0,1,0)+IF(F25>0,1,0)+IF(G25>0,1,0)+IF(H25>0,1,0))/4) -> 0 | J25: =IF($A25="","",IF(I25=1,"Completo",IF(I25=0,"Pendiente","Parcial"))) -> Pendiente
A26: RF-023 | B26: Listar / consultar productos | C26: Gestión de productos | D26: Alta | F26: 0 | G26: 0 | H26: 0 | I26: =IF($A26="","",(IF(E26>0,1,0)+IF(F26>0,1,0)+IF(G26>0,1,0)+IF(H26>0,1,0))/4) -> 0 | J26: =IF($A26="","",IF(I26=1,"Completo",IF(I26=0,"Pendiente","Parcial"))) -> Pendiente
A27: RF-024 | B27: Actualizar producto | C27: Gestión de productos | D27: Alta | F27: 0 | G27: 0 | H27: 0 | I27: =IF($A27="","",(IF(E27>0,1,0)+IF(F27>0,1,0)+IF(G27>0,1,0)+IF(H27>0,1,0))/4) -> 0 | J27: =IF($A27="","",IF(I27=1,"Completo",IF(I27=0,"Pendiente","Parcial"))) -> Pendiente
A28: RF-025 | B28: Deshabilitar producto | C28: Gestión de productos | D28: Alta | F28: 0 | G28: 0 | H28: 0 | I28: =IF($A28="","",(IF(E28>0,1,0)+IF(F28>0,1,0)+IF(G28>0,1,0)+IF(H28>0,1,0))/4) -> 0 | J28: =IF($A28="","",IF(I28=1,"Completo",IF(I28=0,"Pendiente","Parcial"))) -> Pendiente
A29: RF-026 | B29: Reporte de ventas por mes | C29: Reportes y estadisticas | D29: Media | F29: 0 | G29: 0 | H29: 0 | I29: =IF($A29="","",(IF(E29>0,1,0)+IF(F29>0,1,0)+IF(G29>0,1,0)+IF(H29>0,1,0))/4) -> 0 | J29: =IF($A29="","",IF(I29=1,"Completo",IF(I29=0,"Pendiente","Parcial"))) -> Pendiente
A30: RF-027 | B30: Top productos | C30: Reportes y estadisticas | D30: Media | F30: 0 | G30: 0 | H30: 0 | I30: =IF($A30="","",(IF(E30>0,1,0)+IF(F30>0,1,0)+IF(G30>0,1,0)+IF(H30>0,1,0))/4) -> 0 | J30: =IF($A30="","",IF(I30=1,"Completo",IF(I30=0,"Pendiente","Parcial"))) -> Pendiente
A31: RF-028 | B31: Resumen general | C31: Reportes y estadisticas | D31: Media | F31: 0 | G31: 0 | H31: 0 | I31: =IF($A31="","",(IF(E31>0,1,0)+IF(F31>0,1,0)+IF(G31>0,1,0)+IF(H31>0,1,0))/4) -> 0 | J31: =IF($A31="","",IF(I31=1,"Completo",IF(I31=0,"Pendiente","Parcial"))) -> Pendiente
... A38: RF-035 | B38: Eliminar proveedores | C38: Gestión de proveedores | D38: Alta | F38: 0 | G38: 0 | H38: 0 | I38: =IF($A38="","",(IF(E38>0,1,0)+IF(F38>0,1,0)+IF(G38>0,1,0)+IF(H38>0,1,0))/4) -> 0 | J38: =IF($A38="","",IF(I38=1,"Completo",IF(I38=0,"Pendiente","Parcial"))) -> Pendiente
I39: =IF($A39="","",(IF(E39>0,1,0)+IF(F39>0,1,0)+IF(G39>0,1,0)+IF(H39>0,1,0))/4) | J39: =IF($A39="","",IF(I39=1,"Completo",IF(I39=0,"Pendiente","Parcial")))
I40: =IF($A40="","",(IF(E40>0,1,0)+IF(F40>0,1,0)+IF(G40>0,1,0)+IF(H40>0,1,0))/4) | J40: =IF($A40="","",IF(I40=1,"Completo",IF(I40=0,"Pendiente","Parcial")))
I41: =IF($A41="","",(IF(E41>0,1,0)+IF(F41>0,1,0)+IF(G41>0,1,0)+IF(H41>0,1,0))/4) | J41: =IF($A41="","",IF(I41=1,"Completo",IF(I41=0,"Pendiente","Parcial")))
I42: =IF($A42="","",(IF(E42>0,1,0)+IF(F42>0,1,0)+IF(G42>0,1,0)+IF(H42>0,1,0))/4) | J42: =IF($A42="","",IF(I42=1,"Completo",IF(I42=0,"Pendiente","Parcial")))
I43: =IF($A43="","",(IF(E43>0,1,0)+IF(F43>0,1,0)+IF(G43>0,1,0)+IF(H43>0,1,0))/4) | J43: =IF($A43="","",IF(I43=1,"Completo",IF(I43=0,"Pendiente","Parcial")))
I44: =IF($A44="","",(IF(E44>0,1,0)+IF(F44>0,1,0)+IF(G44>0,1,0)+IF(H44>0,1,0))/4) | J44: =IF($A44="","",IF(I44=1,"Completo",IF(I44=0,"Pendiente","Parcial")))
I45: =IF($A45="","",(IF(E45>0,1,0)+IF(F45>0,1,0)+IF(G45>0,1,0)+IF(H45>0,1,0))/4) | J45: =IF($A45="","",IF(I45=1,"Completo",IF(I45=0,"Pendiente","Parcial")))
I46: =IF($A46="","",(IF(E46>0,1,0)+IF(F46>0,1,0)+IF(G46>0,1,0)+IF(H46>0,1,0))/4) | J46: =IF($A46="","",IF(I46=1,"Completo",IF(I46=0,"Pendiente","Parcial")))
I47: =IF($A47="","",(IF(E47>0,1,0)+IF(F47>0,1,0)+IF(G47>0,1,0)+IF(H47>0,1,0))/4) | J47: =IF($A47="","",IF(I47=1,"Completo",IF(I47=0,"Pendiente","Parcial")))
I48: =IF($A48="","",(IF(E48>0,1,0)+IF(F48>0,1,0)+IF(G48>0,1,0)+IF(H48>0,1,0))/4) | J48: =IF($A48="","",IF(I48=1,"Completo",IF(I48=0,"Pendiente","Parcial")))
I49: =IF($A49="","",(IF(E49>0,1,0)+IF(F49>0,1,0)+IF(G49>0,1,0)+IF(H49>0,1,0))/4) | J49: =IF($A49="","",IF(I49=1,"Completo",IF(I49=0,"Pendiente","Parcial")))
...

Sheet Checklist QA
A1: CHECKLIST DE VERIFICACION DE COBERTURA POR REQUISITO
A2: Uso exclusivo de verificacion de cobertura (no reemplaza el registro detallado de casos de prueba).
A3: RF | B3: Nombre del Requisito | C3: Caso(s) de Prueba | D3: Ejecucion Manual | E3: Pruebas Unitarias | F3: Pruebas de Integracion | G3: Evidencia | H3: Estado | I3: Cobertura Completa | J3: Observaciones
A4: =IF('Cobertura de Requisitos'!A4="","",'Cobertura de Requisitos'!A4) -> RF-001 | B4: =IF($A4="","",'Cobertura de Requisitos'!B4) -> Registrar usuario | C4: =IF($A4="","",IF('Cobertura de Requisitos'!E4>0,"Si","No")) -> Si | D4: =IF($A4="","",IF('Cobertura de Requisitos'!F4>0,"Si","No")) -> Si | E4: =IF($A4="","",IF('Cobertura de Requisitos'!G4>0,"Si","No")) -> Si | F4: =IF($A4="","",IF('Cobertura de Requisitos'!H4>0,"Si","No")) -> No | G4: Si | H4: =IF($A4="","",'Cobertura de Requisitos'!J4) -> Parcial | I4: =IF($A4="","",IF(H4="Completo","Si","No")) -> No
A5: =IF('Cobertura de Requisitos'!A5="","",'Cobertura de Requisitos'!A5) -> RF-002 | B5: =IF($A5="","",'Cobertura de Requisitos'!B5) -> Verificar correo electrónico | C5: =IF($A5="","",IF('Cobertura de Requisitos'!E5>0,"Si","No")) -> Si | D5: =IF($A5="","",IF('Cobertura de Requisitos'!F5>0,"Si","No")) -> No | E5: =IF($A5="","",IF('Cobertura de Requisitos'!G5>0,"Si","No")) -> No | F5: =IF($A5="","",IF('Cobertura de Requisitos'!H5>0,"Si","No")) -> No | G5: Si | H5: =IF($A5="","",'Cobertura de Requisitos'!J5) -> Parcial | I5: =IF($A5="","",IF(H5="Completo","Si","No")) -> No
A6: =IF('Cobertura de Requisitos'!A6="","",'Cobertura de Requisitos'!A6) -> RF-003 | B6: =IF($A6="","",'Cobertura de Requisitos'!B6) -> Reenviar código de verificación | C6: =IF($A6="","",IF('Cobertura de Requisitos'!E6>0,"Si","No")) -> Si | D6: =IF($A6="","",IF('Cobertura de Requisitos'!F6>0,"Si","No")) -> No | E6: =IF($A6="","",IF('Cobertura de Requisitos'!G6>0,"Si","No")) -> No | F6: =IF($A6="","",IF('Cobertura de Requisitos'!H6>0,"Si","No")) -> No | G6: Si | H6: =IF($A6="","",'Cobertura de Requisitos'!J6) -> Parcial | I6: =IF($A6="","",IF(H6="Completo","Si","No")) -> No
A7: =IF('Cobertura de Requisitos'!A7="","",'Cobertura de Requisitos'!A7) -> RF-004 | B7: =IF($A7="","",'Cobertura de Requisitos'!B7) -> Inicar sesión | C7: =IF($A7="","",IF('Cobertura de Requisitos'!E7>0,"Si","No")) -> Si | D7: =IF($A7="","",IF('Cobertura de Requisitos'!F7>0,"Si","No")) -> No | E7: =IF($A7="","",IF('Cobertura de Requisitos'!G7>0,"Si","No")) -> No | F7: =IF($A7="","",IF('Cobertura de Requisitos'!H7>0,"Si","No")) -> No | G7: Pendiente | H7: =IF($A7="","",'Cobertura de Requisitos'!J7) -> Parcial | I7: =IF($A7="","",IF(H7="Completo","Si","No")) -> No
A8: =IF('Cobertura de Requisitos'!A8="","",'Cobertura de Requisitos'!A8) -> RF-005 | B8: =IF($A8="","",'Cobertura de Requisitos'!B8) -> Doble factor | C8: =IF($A8="","",IF('Cobertura de Requisitos'!E8>0,"Si","No")) -> Si | D8: =IF($A8="","",IF('Cobertura de Requisitos'!F8>0,"Si","No")) -> No | E8: =IF($A8="","",IF('Cobertura de Requisitos'!G8>0,"Si","No")) -> No | F8: =IF($A8="","",IF('Cobertura de Requisitos'!H8>0,"Si","No")) -> No | G8: Si | H8: =IF($A8="","",'Cobertura de Requisitos'!J8) -> Parcial | I8: =IF($A8="","",IF(H8="Completo","Si","No")) -> No
A9: =IF('Cobertura de Requisitos'!A9="","",'Cobertura de Requisitos'!A9) -> RF-006 | B9: =IF($A9="","",'Cobertura de Requisitos'!B9) -> Verificar código de doble factor(2FA) | C9: =IF($A9="","",IF('Cobertura de Requisitos'!E9>0,"Si","No")) -> Si | D9: =IF($A9="","",IF('Cobertura de Requisitos'!F9>0,"Si","No")) -> No | E9: =IF($A9="","",IF('Cobertura de Requisitos'!G9>0,"Si","No")) -> No | F9: =IF($A9="","",IF('Cobertura de Requisitos'!H9>0,"Si","No")) -> No | G9: Si | H9: =IF($A9="","",'Cobertura de Requisitos'!J9) -> Parcial | I9: =IF($A9="","",IF(H9="Completo","Si","No")) -> No
A10: =IF('Cobertura de Requisitos'!A10="","",'Cobertura de Requisitos'!A10) -> RF-007 | B10: =IF($A10="","",'Cobertura de Requisitos'!B10) -> Solicitar recuperación de contraseña | C10: =IF($A10="","",IF('Cobertura de Requisitos'!E10>0,"Si","No")) -> Si | D10: =IF($A10="","",IF('Cobertura de Requisitos'!F10>0,"Si","No")) -> No | E10: =IF($A10="","",IF('Cobertura de Requisitos'!G10>0,"Si","No")) -> No | F10: =IF($A10="","",IF('Cobertura de Requisitos'!H10>0,"Si","No")) -> No | G10: Si | H10: =IF($A10="","",'Cobertura de Requisitos'!J10) -> Parcial | I10: =IF($A10="","",IF(H10="Completo","Si","No")) -> No
A11: =IF('Cobertura de Requisitos'!A11="","",'Cobertura de Requisitos'!A11) -> RF-008 | B11: =IF($A11="","",'Cobertura de Requisitos'!B11) -> Restablecer contraseña | C11: =IF($A11="","",IF('Cobertura de Requisitos'!E11>0,"Si","No")) -> Si | D11: =IF($A11="","",IF('Cobertura de Requisitos'!F11>0,"Si","No")) -> No | E11: =IF($A11="","",IF('Cobertura de Requisitos'!G11>0,"Si","No")) -> No | F11: =IF($A11="","",IF('Cobertura de Requisitos'!H11>0,"Si","No")) -> No | G11: No | H11: =IF($A11="","",'Cobertura de Requisitos'!J11) -> Parcial | I11: =IF($A11="","",IF(H11="Completo","Si","No")) -> No
A12: =IF('Cobertura de Requisitos'!A12="","",'Cobertura de Requisitos'!A12) -> RF-009 | B12: =IF($A12="","",'Cobertura de Requisitos'!B12) -> Cerrar sesión | C12: =IF($A12="","",IF('Cobertura de Requisitos'!E12>0,"Si","No")) -> Si | D12: =IF($A12="","",IF('Cobertura de Requisitos'!F12>0,"Si","No")) -> No | E12: =IF($A12="","",IF('Cobertura de Requisitos'!G12>0,"Si","No")) -> No | F12: =IF($A12="","",IF('Cobertura de Requisitos'!H12>0,"Si","No")) -> No | G12: Si | H12: =IF($A12="","",'Cobertura de Requisitos'!J12) -> Parcial | I12: =IF($A12="","",IF(H12="Completo","Si","No")) -> No
A13: =IF('Cobertura de Requisitos'!A13="","",'Cobertura de Requisitos'!A13) -> RF-010 | B13: =IF($A13="","",'Cobertura de Requisitos'!B13) -> Registrar usuario | C13: =IF($A13="","",IF('Cobertura de Requisitos'!E13>0,"Si","No")) -> Si | D13: =IF($A13="","",IF('Cobertura de Requisitos'!F13>0,"Si","No")) -> No | E13: =IF($A13="","",IF('Cobertura de Requisitos'!G13>0,"Si","No")) -> No | F13: =IF($A13="","",IF('Cobertura de Requisitos'!H13>0,"Si","No")) -> No | G13: Si | H13: =IF($A13="","",'Cobertura de Requisitos'!J13) -> Parcial | I13: =IF($A13="","",IF(H13="Completo","Si","No")) -> No
A14: =IF('Cobertura de Requisitos'!A14="","",'Cobertura de Requisitos'!A14) -> RF-011 | B14: =IF($A14="","",'Cobertura de Requisitos'!B14) -> Consultar usuario | C14: =IF($A14="","",IF('Cobertura de Requisitos'!E14>0,"Si","No")) -> Si | D14: =IF($A14="","",IF('Cobertura de Requisitos'!F14>0,"Si","No")) -> No | E14: =IF($A14="","",IF('Cobertura de Requisitos'!G14>0,"Si","No")) -> No | F14: =IF($A14="","",IF('Cobertura de Requisitos'!H14>0,"Si","No")) -> No | G14: Si | H14: =IF($A14="","",'Cobertura de Requisitos'!J14) -> Parcial | I14: =IF($A14="","",IF(H14="Completo","Si","No")) -> No
A15: =IF('Cobertura de Requisitos'!A15="","",'Cobertura de Requisitos'!A15) -> RF-012 | B15: =IF($A15="","",'Cobertura de Requisitos'!B15) -> Actualizar usuario | C15: =IF($A15="","",IF('Cobertura de Requisitos'!E15>0,"Si","No")) -> Si | D15: =IF($A15="","",IF('Cobertura de Requisitos'!F15>0,"Si","No")) -> No | E15: =IF($A15="","",IF('Cobertura de Requisitos'!G15>0,"Si","No")) -> No | F15: =IF($A15="","",IF('Cobertura de Requisitos'!H15>0,"Si","No")) -> No | G15: Si | H15: =IF($A15="","",'Cobertura de Requisitos'!J15) -> Parcial | I15: =IF($A15="","",IF(H15="Completo","Si","No")) -> No
... A19: =IF('Cobertura de Requisitos'!A19="","",'Cobertura de Requisitos'!A19) -> RF-016 | B19: =IF($A19="","",'Cobertura de Requisitos'!B19) -> Agregar Producto al Carrito. | C19: =IF($A19="","",IF('Cobertura de Requisitos'!E19>0,"Si","No")) -> Si | D19: =IF($A19="","",IF('Cobertura de Requisitos'!F19>0,"Si","No")) -> No | E19: =IF($A19="","",IF('Cobertura de Requisitos'!G19>0,"Si","No")) -> No | F19: =IF($A19="","",IF('Cobertura de Requisitos'!H19>0,"Si","No")) -> No | G19: Si | H19: =IF($A19="","",'Cobertura de Requisitos'!J19) -> Parcial | I19: =IF($A19="","",IF(H19="Completo","Si","No")) -> No
A20: =IF('Cobertura de Requisitos'!A20="","",'Cobertura de Requisitos'!A20) -> RF-017 | B20: =IF($A20="","",'Cobertura de Requisitos'!B20) -> Visualizar Carrito de Compras | C20: =IF($A20="","",IF('Cobertura de Requisitos'!E20>0,"Si","No")) -> No | D20: =IF($A20="","",IF('Cobertura de Requisitos'!F20>0,"Si","No")) -> No | E20: =IF($A20="","",IF('Cobertura de Requisitos'!G20>0,"Si","No")) -> No | F20: =IF($A20="","",IF('Cobertura de Requisitos'!H20>0,"Si","No")) -> No | H20: =IF($A20="","",'Cobertura de Requisitos'!J20) -> Pendiente | I20: =IF($A20="","",IF(H20="Completo","Si","No")) -> No
A21: =IF('Cobertura de Requisitos'!A21="","",'Cobertura de Requisitos'!A21) -> RF-018 | B21: =IF($A21="","",'Cobertura de Requisitos'!B21) -> Modificar Cantidades en Carrito | C21: =IF($A21="","",IF('Cobertura de Requisitos'!E21>0,"Si","No")) -> No | D21: =IF($A21="","",IF('Cobertura de Requisitos'!F21>0,"Si","No")) -> No | E21: =IF($A21="","",IF('Cobertura de Requisitos'!G21>0,"Si","No")) -> No | F21: =IF($A21="","",IF('Cobertura de Requisitos'!H21>0,"Si","No")) -> No | H21: =IF($A21="","",'Cobertura de Requisitos'!J21) -> Pendiente | I21: =IF($A21="","",IF(H21="Completo","Si","No")) -> No
A22: =IF('Cobertura de Requisitos'!A22="","",'Cobertura de Requisitos'!A22) -> RF-019 | B22: =IF($A22="","",'Cobertura de Requisitos'!B22) -> Seleccionar Método de Pago | C22: =IF($A22="","",IF('Cobertura de Requisitos'!E22>0,"Si","No")) -> No | D22: =IF($A22="","",IF('Cobertura de Requisitos'!F22>0,"Si","No")) -> No | E22: =IF($A22="","",IF('Cobertura de Requisitos'!G22>0,"Si","No")) -> No | F22: =IF($A22="","",IF('Cobertura de Requisitos'!H22>0,"Si","No")) -> No | H22: =IF($A22="","",'Cobertura de Requisitos'!J22) -> Pendiente | I22: =IF($A22="","",IF(H22="Completo","Si","No")) -> No
A23: =IF('Cobertura de Requisitos'!A23="","",'Cobertura de Requisitos'!A23) -> RF-020 | B23: =IF($A23="","",'Cobertura de Requisitos'!B23) -> Confirmar Compra | C23: =IF($A23="","",IF('Cobertura de Requisitos'!E23>0,"Si","No")) -> No | D23: =IF($A23="","",IF('Cobertura de Requisitos'!F23>0,"Si","No")) -> No | E23: =IF($A23="","",IF('Cobertura de Requisitos'!G23>0,"Si","No")) -> No | F23: =IF($A23="","",IF('Cobertura de Requisitos'!H23>0,"Si","No")) -> No | H23: =IF($A23="","",'Cobertura de Requisitos'!J23) -> Pendiente | I23: =IF($A23="","",IF(H23="Completo","Si","No")) -> No
A24: =IF('Cobertura de Requisitos'!A24="","",'Cobertura de Requisitos'!A24) -> RF-021 | B24: =IF($A24="","",'Cobertura de Requisitos'!B24) -> Comprobante de Venta | C24: =IF($A24="","",IF('Cobertura de Requisitos'!E24>0,"Si","No")) -> No | D24: =IF($A24="","",IF('Cobertura de Requisitos'!F24>0,"Si","No")) -> No | E24: =IF($A24="","",IF('Cobertura de Requisitos'!G24>0,"Si","No")) -> No | F24: =IF($A24="","",IF('Cobertura de Requisitos'!H24>0,"Si","No")) -> No | H24: =IF($A24="","",'Cobertura de Requisitos'!J24) -> Pendiente | I24: =IF($A24="","",IF(H24="Completo","Si","No")) -> No
A25: =IF('Cobertura de Requisitos'!A25="","",'Cobertura de Requisitos'!A25) -> RF-022 | B25: =IF($A25="","",'Cobertura de Requisitos'!B25) -> Registrar Producto | C25: =IF($A25="","",IF('Cobertura de Requisitos'!E25>0,"Si","No")) -> No | D25: =IF($A25="","",IF('Cobertura de Requisitos'!F25>0,"Si","No")) -> No | E25: =IF($A25="","",IF('Cobertura de Requisitos'!G25>0,"Si","No")) -> No | F25: =IF($A25="","",IF('Cobertura de Requisitos'!H25>0,"Si","No")) -> No | H25: =IF($A25="","",'Cobertura de Requisitos'!J25) -> Pendiente | I25: =IF($A25="","",IF(H25="Completo","Si","No")) -> No
A26: =IF('Cobertura de Requisitos'!A26="","",'Cobertura de Requisitos'!A26) -> RF-023 | B26: =IF($A26="","",'Cobertura de Requisitos'!B26) -> Listar / consultar productos | C26: =IF($A26="","",IF('Cobertura de Requisitos'!E26>0,"Si","No")) -> No | D26: =IF($A26="","",IF('Cobertura de Requisitos'!F26>0,"Si","No")) -> No | E26: =IF($A26="","",IF('Cobertura de Requisitos'!G26>0,"Si","No")) -> No | F26: =IF($A26="","",IF('Cobertura de Requisitos'!H26>0,"Si","No")) -> No | H26: =IF($A26="","",'Cobertura de Requisitos'!J26) -> Pendiente | I26: =IF($A26="","",IF(H26="Completo","Si","No")) -> No
A27: =IF('Cobertura de Requisitos'!A27="","",'Cobertura de Requisitos'!A27) -> RF-024 | B27: =IF($A27="","",'Cobertura de Requisitos'!B27) -> Actualizar producto | C27: =IF($A27="","",IF('Cobertura de Requisitos'!E27>0,"Si","No")) -> No | D27: =IF($A27="","",IF('Cobertura de Requisitos'!F27>0,"Si","No")) -> No | E27: =IF($A27="","",IF('Cobertura de Requisitos'!G27>0,"Si","No")) -> No | F27: =IF($A27="","",IF('Cobertura de Requisitos'!H27>0,"Si","No")) -> No | H27: =IF($A27="","",'Cobertura de Requisitos'!J27) -> Pendiente | I27: =IF($A27="","",IF(H27="Completo","Si","No")) -> No
A28: =IF('Cobertura de Requisitos'!A28="","",'Cobertura de Requisitos'!A28) -> RF-025 | B28: =IF($A28="","",'Cobertura de Requisitos'!B28) -> Deshabilitar producto | C28: =IF($A28="","",IF('Cobertura de Requisitos'!E28>0,"Si","No")) -> No | D28: =IF($A28="","",IF('Cobertura de Requisitos'!F28>0,"Si","No")) -> No | E28: =IF($A28="","",IF('Cobertura de Requisitos'!G28>0,"Si","No")) -> No | F28: =IF($A28="","",IF('Cobertura de Requisitos'!H28>0,"Si","No")) -> No | H28: =IF($A28="","",'Cobertura de Requisitos'!J28) -> Pendiente | I28: =IF($A28="","",IF(H28="Completo","Si","No")) -> No
A29: =IF('Cobertura de Requisitos'!A29="","",'Cobertura de Requisitos'!A29) -> RF-026 | B29: =IF($A29="","",'Cobertura de Requisitos'!B29) -> Reporte de ventas por mes | C29: =IF($A29="","",IF('Cobertura de Requisitos'!E29>0,"Si","No")) -> No | D29: =IF($A29="","",IF('Cobertura de Requisitos'!F29>0,"Si","No")) -> No | E29: =IF($A29="","",IF('Cobertura de Requisitos'!G29>0,"Si","No")) -> No | F29: =IF($A29="","",IF('Cobertura de Requisitos'!H29>0,"Si","No")) -> No | H29: =IF($A29="","",'Cobertura de Requisitos'!J29) -> Pendiente | I29: =IF($A29="","",IF(H29="Completo","Si","No")) -> No
A30: =IF('Cobertura de Requisitos'!A30="","",'Cobertura de Requisitos'!A30) -> RF-027 | B30: =IF($A30="","",'Cobertura de Requisitos'!B30) -> Top productos | C30: =IF($A30="","",IF('Cobertura de Requisitos'!E30>0,"Si","No")) -> No | D30: =IF($A30="","",IF('Cobertura de Requisitos'!F30>0,"Si","No")) -> No | E30: =IF($A30="","",IF('Cobertura de Requisitos'!G30>0,"Si","No")) -> No | F30: =IF($A30="","",IF('Cobertura de Requisitos'!H30>0,"Si","No")) -> No | H30: =IF($A30="","",'Cobertura de Requisitos'!J30) -> Pendiente | I30: =IF($A30="","",IF(H30="Completo","Si","No")) -> No
A31: =IF('Cobertura de Requisitos'!A31="","",'Cobertura de Requisitos'!A31) -> RF-028 | B31: =IF($A31="","",'Cobertura de Requisitos'!B31) -> Resumen general | C31: =IF($A31="","",IF('Cobertura de Requisitos'!E31>0,"Si","No")) -> No | D31: =IF($A31="","",IF('Cobertura de Requisitos'!F31>0,"Si","No")) -> No | E31: =IF($A31="","",IF('Cobertura de Requisitos'!G31>0,"Si","No")) -> No | F31: =IF($A31="","",IF('Cobertura de Requisitos'!H31>0,"Si","No")) -> No | H31: =IF($A31="","",'Cobertura de Requisitos'!J31) -> Pendiente | I31: =IF($A31="","",IF(H31="Completo","Si","No")) -> No
... A149: =IF('Cobertura de Requisitos'!A149="","",'Cobertura de Requisitos'!A149) | B149: =IF($A149="","",'Cobertura de Requisitos'!B149) | C149: =IF($A149="","",IF('Cobertura de Requisitos'!E149>0,"Si","No")) | D149: =IF($A149="","",IF('Cobertura de Requisitos'!F149>0,"Si","No")) | E149: =IF($A149="","",IF('Cobertura de Requisitos'!G149>0,"Si","No")) | F149: =IF($A149="","",IF('Cobertura de Requisitos'!H149>0,"Si","No")) | H149: =IF($A149="","",'Cobertura de Requisitos'!J149) | I149: =IF($A149="","",IF(H149="Completo","Si","No"))

Sheet Metricas
A1: METRICAS DE COBERTURA Y CALIDAD
A3: COBERTURA POR MODULO
A4: Modulo | B4: Total RF | C4: RF Completos | D4: RF Parciales | E4: RF Pendientes | F4: Cobertura (%)
A5: Autenticacion | B5: =COUNTIF('Cobertura de Requisitos'!C4:C149,$A5) -> 9 | C5: =COUNTIFS('Cobertura de Requisitos'!C4:C149,$A5,'Cobertura de Requisitos'!J4:J149,"Completo") -> 0 | D5: =COUNTIFS('Cobertura de Requisitos'!C4:C149,$A5,'Cobertura de Requisitos'!J4:J149,"Parcial") -> 9 | E5: =COUNTIFS('Cobertura de Requisitos'!C4:C149,$A5,'Cobertura de Requisitos'!J4:J149,"Pendiente") -> 0 | F5: =IFERROR(AVERAGEIFS('Cobertura de Requisitos'!I4:I149,'Cobertura de Requisitos'!C4:C149,$A5),0) -> 0.30555556
A6: Gestion de Usuarios | B6: =COUNTIF('Cobertura de Requisitos'!C4:C149,$A6) -> 4 | C6: =COUNTIFS('Cobertura de Requisitos'!C4:C149,$A6,'Cobertura de Requisitos'!J4:J149,"Completo") -> 0 | D6: =COUNTIFS('Cobertura de Requisitos'!C4:C149,$A6,'Cobertura de Requisitos'!J4:J149,"Parcial") -> 4 | E6: =COUNTIFS('Cobertura de Requisitos'!C4:C149,$A6,'Cobertura de Requisitos'!J4:J149,"Pendiente") -> 0 | F6: =IFERROR(AVERAGEIFS('Cobertura de Requisitos'!I4:I149,'Cobertura de Requisitos'!C4:C149,$A6),0) -> 0.25
A7: Ventas | B7: =COUNTIF('Cobertura de Requisitos'!C4:C149,$A7) -> 8 | C7: =COUNTIFS('Cobertura de Requisitos'!C4:C149,$A7,'Cobertura de Requisitos'!J4:J149,"Completo") -> 0 | D7: =COUNTIFS('Cobertura de Requisitos'!C4:C149,$A7,'Cobertura de Requisitos'!J4:J149,"Parcial") -> 2 | E7: =COUNTIFS('Cobertura de Requisitos'!C4:C149,$A7,'Cobertura de Requisitos'!J4:J149,"Pendiente") -> 6 | F7: =IFERROR(AVERAGEIFS('Cobertura de Requisitos'!I4:I149,'Cobertura de Requisitos'!C4:C149,$A7),0) -> 0.0625
A8: Gestión de productos | B8: =COUNTIF('Cobertura de Requisitos'!C4:C149,$A8) -> 4 | C8: =COUNTIFS('Cobertura de Requisitos'!C4:C149,$A8,'Cobertura de Requisitos'!J4:J149,"Completo") -> 0 | D8: =COUNTIFS('Cobertura de Requisitos'!C4:C149,$A8,'Cobertura de Requisitos'!J4:J149,"Parcial") -> 0 | E8: =COUNTIFS('Cobertura de Requisitos'!C4:C149,$A8,'Cobertura de Requisitos'!J4:J149,"Pendiente") -> 4 | F8: =IFERROR(AVERAGEIFS('Cobertura de Requisitos'!I4:I149,'Cobertura de Requisitos'!C4:C149,$A8),0) -> 0
A9: Inventario | B9: =COUNTIF('Cobertura de Requisitos'!C4:C149,$A9) -> 2 | C9: =COUNTIFS('Cobertura de Requisitos'!C4:C149,$A9,'Cobertura de Requisitos'!J4:J149,"Completo") -> 0 | D9: =COUNTIFS('Cobertura de Requisitos'!C4:C149,$A9,'Cobertura de Requisitos'!J4:J149,"Parcial") -> 0 | E9: =COUNTIFS('Cobertura de Requisitos'!C4:C149,$A9,'Cobertura de Requisitos'!J4:J149,"Pendiente") -> 2 | F9: =IFERROR(AVERAGEIFS('Cobertura de Requisitos'!I4:I149,'Cobertura de Requisitos'!C4:C149,$A9),0) -> 0
A10: Reportes y estadisticas | B10: =COUNTIF('Cobertura de Requisitos'!C4:C149,$A10) -> 4 | C10: =COUNTIFS('Cobertura de Requisitos'!C4:C149,$A10,'Cobertura de Requisitos'!J4:J149,"Completo") -> 0 | D10: =COUNTIFS('Cobertura de Requisitos'!C4:C149,$A10,'Cobertura de Requisitos'!J4:J149,"Parcial") -> 0 | E10: =COUNTIFS('Cobertura de Requisitos'!C4:C149,$A10,'Cobertura de Requisitos'!J4:J149,"Pendiente") -> 4 | F10: =IFERROR(AVERAGEIFS('Cobertura de Requisitos'!I4:I149,'Cobertura de Requisitos'!C4:C149,$A10),0) -> 0
A11: Gestión de proveedores | B11: =COUNTIF('Cobertura de Requisitos'!C5:C150,$A11) -> 4 | C11: =COUNTIFS('Cobertura de Requisitos'!C5:C150,$A11,'Cobertura de Requisitos'!J5:J150,"Completo") -> 0 | D11: =COUNTIFS('Cobertura de Requisitos'!C5:C150,$A11,'Cobertura de Requisitos'!J5:J150,"Parcial") -> 0 | E11: =COUNTIFS('Cobertura de Requisitos'!C5:C150,$A11,'Cobertura de Requisitos'!J5:J150,"Pendiente") -> 4 | F11: =IFERROR(AVERAGEIFS('Cobertura de Requisitos'!I5:I150,'Cobertura de Requisitos'!C5:C150,$A11),0) -> 0
A14: COBERTURA POR PRIORIDAD
A15: Prioridad | B15: Total RF | F15: Cobertura (%)
A16: Alta | B16: =COUNTIF('Cobertura de Requisitos'!D4:D149,$A16) -> 29 | F16: =IFERROR(AVERAGEIFS('Cobertura de Requisitos'!I4:I149,'Cobertura de Requisitos'!D4:D149,$A16),0) -> 0.14655172
A17: Media | B17: =COUNTIF('Cobertura de Requisitos'!D4:D149,$A17) -> 6 | F17: =IFERROR(AVERAGEIFS('Cobertura de Requisitos'!I4:I149,'Cobertura de Requisitos'!D4:D149,$A17),0) -> 0
A18: Baja | B18: =COUNTIF('Cobertura de Requisitos'!D4:D149,$A18) -> 0 | F18: =IFERROR(AVERAGEIFS('Cobertura de Requisitos'!I4:I149,'Cobertura de Requisitos'!D4:D149,$A18),0) -> 0
A21: INDICADORES GLOBALES
A22: % RF Cubiertos (Completo + Parcial) | B22: =Dashboard!C6/Dashboard!C5 -> 0.42857143
A23: % RF Pendientes | B23: =Dashboard!C7/Dashboard!C5 -> 0.57142857
A24: Cantidad de Pruebas Manuales | B24: =Dashboard!C9 -> 8
A25: Cantidad de Pruebas Unitarias | B25: =Dashboard!F5 -> 8
A26: Cantidad de Pruebas de Integracion | B26: =Dashboard!F6 -> 0
A27: Total de Ejecuciones (Manual+Unit.+Integ.) | B27: =Dashboard!C9+Dashboard!F5+Dashboard!F6 -> 16
A28: Numero de Defectos Encontrados | B28: =Dashboard!F13 -> 14
A29: Numero de Defectos Corregidos | B29: =Dashboard!G13 -> 11
A31: COBERTURA POR TIPO DE PRUEBA
A32: Manual | B32: =Dashboard!I7 -> 0.028571429
A33: Unitaria | B33: =Dashboard!I8 -> 0.028571429
A34: Integracion | B34: =Dashboard!I9 -> 0
